<?xml version="1.0" ?>
<!-- =================================================================================== -->
<!-- |    This document was autogenerated by xacro from thormang3.xacro                | -->
<!-- |    EDITING THIS FILE BY HAND IS NOT RECOMMENDED                                 | -->
<!-- =================================================================================== -->
<robot name="johnny5" xmlns:xacro="http://ros.org/wiki/xacro">
  <!-- ros_control plugin -->
  <gazebo>
    <plugin filename="libgazebo_ros_control.so" name="gazebo_ros_control">
      <robotNamespace>/gazebo/johnny5/joints</robotNamespace>
      <robotParam>/johnny5/robot_description</robotParam>
      <robotSimType>gazebo_ros_control/DefaultRobotHWSim</robotSimType>
    </plugin>
  </gazebo>
  <!-- p3d plugin -->
  <gazebo>
    <plugin filename="libgazebo_ros_p3d.so" name="ground_truth">
      <frameName>world</frameName>
      <bodyName>pelvis_link</bodyName>
      <topicName>/gazebo/johnny5/pelvis_odom</topicName>
      <updateRate>125.0</updateRate>
    </plugin>
  </gazebo>
  <!-- camera plugin -->
  <gazebo reference="cam_link">
    <sensor name="center_camera_gz" type="camera">
      <update_rate>30.0</update_rate>
      <camera name="web_cam">
        <horizontal_fov>1.3962634</horizontal_fov>
        <image>
          <width>640</width>
          <height>480</height>
          <format>R8G8B8</format>
        </image>
        <clip>
          <near>0.02</near>
          <far>300</far>
        </clip>
      </camera>
      <plugin filename="libgazebo_ros_camera.so" name="camera_controller">
        <alwaysOn>true</alwaysOn>
        <updateRate>0.0</updateRate>
        <cameraName>camera</cameraName>
        <imageTopicName>/johnny5/sensor/camera/image_raw</imageTopicName>
        <cameraInfoTopicName>/johnny5/sensor/camera/camera_info</cameraInfoTopicName>
        <frameName>cam_link</frameName>
        <hackBaseline>0.07</hackBaseline>
        <distortionK1>0.0</distortionK1>
        <distortionK2>0.0</distortionK2>
        <distortionK3>0.0</distortionK3>
        <distortionT1>0.0</distortionT1>
        <distortionT2>0.0</distortionT2>
      </plugin>
    </sensor>
  </gazebo>
  <!-- lidar plugin -->
  <gazebo reference="lidar_link">
    <sensor name="head_hokuyo_sensor" type="gpu_ray">
      <pose>0 0 0 0 0 0</pose>
      <visualize>false</visualize>
      <update_rate>40</update_rate>
      <ray>
        <scan>
          <horizontal>
            <samples>720</samples>
            <resolution>1</resolution>
            <min_angle>-1.3</min_angle>
            <max_angle>1.0</max_angle>
          </horizontal>
        </scan>
        <range>
          <min>0.10</min>
          <max>6.0</max>
          <resolution>0.01</resolution>
        </range>
        <noise>
          <type>gaussian</type>
          <mean>0.0</mean>
          <stddev>0.01</stddev>
        </noise>
      </ray>
      <plugin filename="libgazebo_ros_gpu_laser.so" name="gazebo_ros_head_hokuyo_controller">
        <topicName>/johnny5/sensor/laser/scan</topicName>
        <frameName>lidar_link</frameName>
      </plugin>
    </sensor>
  </gazebo>
  <!-- imu plugin -->
  <gazebo>
    <plugin filename="libhector_gazebo_ros_imu.so" name="imu_link">
      <alwaysOn>true</alwaysOn>
      <updateRate>125.0</updateRate>
      <bodyName>imu_link</bodyName>
      <topicName>/gazebo/johnny5/sensor/imu</topicName>
      <accelDrift>0.0 0.0 0.0</accelDrift>
      <accelGaussianNoise>0.1 0.1 0.1</accelGaussianNoise>
      <rateDrift>0.0 0.0 0.0</rateDrift>
      <rateGaussianNoise>0.05 0.05 0.05</rateGaussianNoise>
      <headingDrift>0.0</headingDrift>
      <headingGaussianNoise>0.05</headingGaussianNoise>
      <rpyOffsets>0.0 0.0 3.14159265359</rpyOffsets>
    </plugin>
  </gazebo>
  <!-- FT sensors -->
  <!-- Left leg -->
  <gazebo reference="l_leg_ft">
    <provideFeedback>true</provideFeedback>
  </gazebo>
  <gazebo>
    <plugin filename="libgazebo_ros_ft_sensor.so" name="ft_sensor">
      <updateRate>125.0</updateRate>
      <topicName>/gazebo/johnny5/sensor/ft/left_foot</topicName>
      <jointName>l_leg_ft</jointName>
    </plugin>
  </gazebo>
  <!-- Right leg -->
  <gazebo reference="r_leg_ft">
    <provideFeedback>true</provideFeedback>
  </gazebo>
  <gazebo>
    <plugin filename="libgazebo_ros_ft_sensor.so" name="ft_sensor">
      <updateRate>125.0</updateRate>
      <topicName>/gazebo/johnny5/sensor/ft/right_foot</topicName>
      <jointName>r_leg_ft</jointName>
    </plugin>
  </gazebo>
  <!-- Left hand -->
  <gazebo reference="l_arm_ft">
    <provideFeedback>true</provideFeedback>
  </gazebo>
  <gazebo>
    <plugin filename="libgazebo_ros_ft_sensor.so" name="ft_sensor">
      <updateRate>125.0</updateRate>
      <topicName>/gazebo/johnny5/sensor/ft/left_wrist</topicName>
      <jointName>l_arm_ft</jointName>
    </plugin>
  </gazebo>
  <!-- Right hand -->
  <gazebo reference="r_arm_ft">
    <provideFeedback>true</provideFeedback>
  </gazebo>
  <gazebo>
    <plugin filename="libgazebo_ros_ft_sensor.so" name="ft_sensor">
      <updateRate>125.0</updateRate>
      <topicName>/gazebo/johnny5/sensor/ft/right_wrist</topicName>
      <jointName>r_arm_ft</jointName>
    </plugin>
  </gazebo>
  <!-- World -->
  <gazebo reference="world">
  </gazebo>
  <!-- Base -->
  <gazebo reference="base">
  </gazebo>
  <!-- Body-->
  <gazebo reference="pelvis_link">
    <mu1>0.2</mu1>
    <mu2>0.2</mu2>
    <material>Gazebo/Grey</material>
  </gazebo>
  <gazebo reference="chest_link">
    <mu1>0.2</mu1>
    <mu2>0.2</mu2>
    <material>Gazebo/Grey</material>
  </gazebo>
  <!-- Head -->
  <gazebo reference="head_y_link">
    <mu1>0.2</mu1>
    <mu2>0.2</mu2>
    <material>Gazebo/Grey</material>
  </gazebo>
  <gazebo reference="head_p_link">
    <mu1>0.2</mu1>
    <mu2>0.2</mu2>
    <material>Gazebo/Grey</material>
  </gazebo>
  <gazebo reference="lidar_link">
  </gazebo>
  <!-- Left Arm -->
  <gazebo reference="l_arm_sh_p1_link">
    <mu1>0.2</mu1>
    <mu2>0.2</mu2>
    <material>Gazebo/Grey</material>
  </gazebo>
  <gazebo reference="l_arm_sh_r_link">
    <mu1>0.2</mu1>
    <mu2>0.2</mu2>
    <material>Gazebo/Grey</material>
  </gazebo>
  <gazebo reference="l_arm_sh_p2_link">
    <mu1>0.2</mu1>
    <mu2>0.2</mu2>
    <material>Gazebo/Grey</material>
  </gazebo>
  <gazebo reference="l_arm_el_y_link">
    <mu1>0.2</mu1>
    <mu2>0.2</mu2>
    <material>Gazebo/Grey</material>
  </gazebo>
  <gazebo reference="l_arm_wr_r_link">
    <mu1>0.2</mu1>
    <mu2>0.2</mu2>
    <material>Gazebo/Grey</material>
  </gazebo>
  <gazebo reference="l_arm_wr_y_link">
    <mu1>0.2</mu1>
    <mu2>0.2</mu2>
    <material>Gazebo/Grey</material>
  </gazebo>
  <gazebo reference="l_arm_wr_p_link">
    <mu1>0.2</mu1>
    <mu2>0.2</mu2>
    <material>Gazebo/Grey</material>
  </gazebo>
  <gazebo reference="l_arm_grip_link">
    <mu1>0.2</mu1>
    <mu2>0.2</mu2>
    <material>Gazebo/Grey</material>
  </gazebo>
  <gazebo reference="l_arm_grip_1_link">
    <mu1>0.2</mu1>
    <mu2>0.2</mu2>
    <material>Gazebo/Grey</material>
  </gazebo>
  <gazebo reference="l_arm_end_link">
    <mu1>0.2</mu1>
    <mu2>0.2</mu2>
    <material>Gazebo/Red</material>
  </gazebo>
  <!-- Right Arm -->
  <gazebo reference="r_arm_sh_p1_link">
    <mu1>0.2</mu1>
    <mu2>0.2</mu2>
    <material>Gazebo/Grey</material>
  </gazebo>
  <gazebo reference="r_arm_sh_r_link">
    <mu1>0.2</mu1>
    <mu2>0.2</mu2>
    <material>Gazebo/Grey</material>
  </gazebo>
  <gazebo reference="r_arm_sh_p2_link">
    <mu1>0.2</mu1>
    <mu2>0.2</mu2>
    <material>Gazebo/Grey</material>
  </gazebo>
  <gazebo reference="r_arm_el_y_link">
    <mu1>0.2</mu1>
    <mu2>0.2</mu2>
    <material>Gazebo/Grey</material>
  </gazebo>
  <gazebo reference="r_arm_wr_r_link">
    <mu1>0.2</mu1>
    <mu2>0.2</mu2>
    <material>Gazebo/Grey</material>
  </gazebo>
  <gazebo reference="r_arm_wr_y_link">
    <mu1>0.2</mu1>
    <mu2>0.2</mu2>
    <material>Gazebo/Grey</material>
  </gazebo>
  <gazebo reference="r_arm_wr_p_link">
    <mu1>0.2</mu1>
    <mu2>0.2</mu2>
    <material>Gazebo/Grey</material>
  </gazebo>
  <gazebo reference="r_arm_grip_link">
    <mu1>0.2</mu1>
    <mu2>0.2</mu2>
    <material>Gazebo/Grey</material>
  </gazebo>
  <gazebo reference="r_arm_grip_1_link">
    <mu1>0.2</mu1>
    <mu2>0.2</mu2>
    <material>Gazebo/Grey</material>
  </gazebo>
  <gazebo reference="r_arm_end_link">
    <mu1>0.2</mu1>
    <mu2>0.2</mu2>
    <material>Gazebo/Red</material>
  </gazebo>
  <!-- Left Leg -->
  <gazebo reference="l_leg_hip_y_link">
    <mu1>0.2</mu1>
    <mu2>0.2</mu2>
    <material>Gazebo/Grey</material>
  </gazebo>
  <gazebo reference="l_leg_hip_r_link">
    <mu1>0.2</mu1>
    <mu2>0.2</mu2>
    <material>Gazebo/Grey</material>
  </gazebo>
  <gazebo reference="l_leg_hip_p_link">
    <mu1>0.2</mu1>
    <mu2>0.2</mu2>
    <material>Gazebo/Grey</material>
  </gazebo>
  <gazebo reference="l_leg_kn_p_link">
    <mu1>0.2</mu1>
    <mu2>0.2</mu2>
    <material>Gazebo/Grey</material>
  </gazebo>
  <gazebo reference="l_leg_an_p_link">
    <mu1>0.2</mu1>
    <mu2>0.2</mu2>
    <material>Gazebo/Grey</material>
  </gazebo>
  <gazebo reference="l_leg_an_r_link">
    <mu1>0.2</mu1>
    <mu2>0.2</mu2>
    <material>Gazebo/Grey</material>
  </gazebo>
  <gazebo reference="l_leg_foot_link">
    <mu1>0.2</mu1>
    <mu2>0.2</mu2>
    <material>Gazebo/Grey</material>
  </gazebo>
  <!-- Right Leg -->
  <gazebo reference="r_leg_hip_y_link">
    <mu1>0.2</mu1>
    <mu2>0.2</mu2>
    <material>Gazebo/Grey</material>
  </gazebo>
  <gazebo reference="r_leg_hip_r_link">
    <mu1>0.2</mu1>
    <mu2>0.2</mu2>
    <material>Gazebo/Grey</material>
  </gazebo>
  <gazebo reference="r_leg_hip_p_link">
    <mu1>0.2</mu1>
    <mu2>0.2</mu2>
    <material>Gazebo/Grey</material>
  </gazebo>
  <gazebo reference="r_leg_kn_p_link">
    <mu1>0.2</mu1>
    <mu2>0.2</mu2>
    <material>Gazebo/Grey</material>
  </gazebo>
  <gazebo reference="r_leg_an_p_link">
    <mu1>0.2</mu1>
    <mu2>0.2</mu2>
    <material>Gazebo/Grey</material>
  </gazebo>
  <gazebo reference="r_leg_an_r_link">
    <mu1>0.2</mu1>
    <mu2>0.2</mu2>
    <material>Gazebo/Grey</material>
  </gazebo>
  <gazebo reference="r_leg_foot_link">
    <mu1>0.2</mu1>
    <mu2>0.2</mu2>
    <material>Gazebo/Grey</material>
  </gazebo>
  <material name="black">
    <color rgba="0.0 0.0 0.0 1.0"/>
  </material>
  <material name="blue">
    <color rgba="0.0 0.0 0.8 1.0"/>
  </material>
  <material name="green">
    <color rgba="0.0 0.8 0.0 1.0"/>
  </material>
  <material name="grey">
    <color rgba="0.2 0.2 0.2 1.0"/>
  </material>
  <material name="orange">
    <color rgba="1.0 0.423529411765 0.0392156862745 1.0"/>
  </material>
  <material name="brown">
    <color rgba="0.870588235294 0.811764705882 0.764705882353 1.0"/>
  </material>
  <material name="red">
    <color rgba="0.8 0.0 0.0 1.0"/>
  </material>
  <material name="white">
    <color rgba="1.0 1.0 1.0 1.0"/>
  </material>
  <!-- link list -->
  <link name="l_f1_link_0">
    <visual>
      <origin rpy="0 0 0" xyz="0 0 0"/>
      <geometry>
        <mesh filename="package://thor_vt_hand_description/meshes/collision/l_f1_link_0.stl"/>
      </geometry>
      <material name="green">
        <color rgba="0 1 0 1"/>
      </material>
    </visual>
    <visual>
      <origin rpy="0.4 0 0" xyz="0 -0.00407 0.04983"/>
      <geometry>
        <mesh filename="package://thor_vt_hand_description/meshes/collision/l_f1_link_1.stl"/>
      </geometry>
      <material name="green"/>
    </visual>
    <collision>
      <origin rpy="0 1.57079632679 0" xyz="0 0 0"/>
      <geometry>
        <cylinder length="0.02" radius="0.017"/>
      </geometry>
      <material name="yellow">
        <color rgba="0 1 1 1"/>
      </material>
    </collision>
    <collision>
      <origin rpy="0 0 0" xyz="0 0 0.02"/>
      <geometry>
        <cylinder length="0.04" radius="0.008"/>
      </geometry>
      <material name="yellow"/>
    </collision>
    <collision>
      <origin rpy="0 1.57079632679 0" xyz="0 -0.00407 0.042"/>
      <geometry>
        <cylinder length="0.02" radius="0.014"/>
      </geometry>
      <material name="yellow">
        <color rgba="0 1 1 1"/>
      </material>
    </collision>
    <collision>
      <!--<origin xyz="0 -0.00407 0.04983" rpy="0.4 0 0"/>-->
      <origin rpy="0.4 0 0" xyz="0.001 -0.00207 0.06783 "/>
      <geometry>
        <cylinder length="0.05" radius="0.008"/>
      </geometry>
      <material name="yellow"/>
    </collision>
    <!-- WARNING: INERTIA NOT CORRECT -->
    <inertial>
      <origin rpy="0 0 0" xyz="0.0002 0.92e-03 21.11e-03"/>
      <mass value="0.1"/>
      <inertia ixx="21.39e-06" ixy="-3.9e-07" ixz="7.1e-07" iyy="18.98e-06" iyz="-1.36e-06" izz="4.73e-06"/>
    </inertial>
  </link>
  <gazebo reference="l_f1_link_0">
    <mu1>1.1</mu1>
    <mu2>1.1</mu2>
    <kp>1000000.0</kp>
    <kd>10.0</kd>
    <maxVel>0.1</maxVel>
    <minDepth>0.00</minDepth>
    <maxContacts>1</maxContacts>
  </gazebo>
  <!--    <link name="${prefix}_link_1">
      <visual>
        <origin xyz="0 0 0" rpy="0 0 0"/>
        <geometry>
          <mesh filename="package://thor_vt_hand_description/meshes/collision/${prefix}_link_1.stl"/>
        </geometry>
        <material name="green"/>
      </visual>
      <collision>
        <origin xyz="-0.002 0.007 0.018" rpy="0 0 0"/>
        <geometry>
          <cylinder length="0.05" radius="0.008"/>
        </geometry>
        <material name="yellow"/>
      </collision>
    </link>-->
  <!--    <gazebo reference="${prefix}_link_1">
      <mu1>1.1</mu1>
      <mu2>1.1</mu2>
      <kp>1000000.0</kp>
      <kd>10.0</kd>
      <maxVel>0.1</maxVel>
      <minDepth>0.00</minDepth>
      <maxContacts>1</maxContacts>

    </gazebo>-->
  <!-- end of link list -->
  <!-- joint list -->
  <!-- WARNING: UPPER LIMIT NOT CORRECT/IGNORED WHILE USING MIMIC JOINT TYPE -->
  <!--		
                <joint name="${prefix}_j1" type="revolute">
                        <parent link="${prefix}_link_0"/>
                        <child link="${prefix}_link_1"/>
                        <axis xyz="1 0 0"/>
                        <origin xyz="0 -0.00407 0.04983" rpy="0.4 0 0"/>
                        <limit lower="0" upper="0.8" effort="100" velocity="100"/>
                        <mimic joint="${prefix}_j0" multiplier="0.4" offset="0"/>
                </joint>
                -->
  <!--   
    <joint name="${prefix}_j1" type="fixed">
      <parent link="${prefix}_link_0"/>
      <child link="${prefix}_link_1"/>
      <axis xyz="1 0 0"/>
      <origin xyz="0 -0.00407 0.04983" rpy="0.4 0 0"/>
      <limit lower="0" upper="0.8" effort="100" velocity="100"/>
    </joint>
    -->
  <!-- end of joint list -->
  <!-- link list -->
  <link name="l_f0_link_0">
    <visual>
      <origin rpy="0 0 0" xyz="0 0 0"/>
      <geometry>
        <mesh filename="package://thor_vt_hand_description/meshes/collision/l_f0_link_0.stl"/>
      </geometry>
      <material name="green">
        <color rgba="0 1 0 1"/>
      </material>
    </visual>
    <visual>
      <origin rpy="0.4 0 0" xyz="0 -0.00407 0.04983"/>
      <geometry>
        <mesh filename="package://thor_vt_hand_description/meshes/collision/l_f0_link_1.stl"/>
      </geometry>
      <material name="green"/>
    </visual>
    <collision>
      <origin rpy="0 1.57079632679 0" xyz="0 0 0"/>
      <geometry>
        <cylinder length="0.02" radius="0.017"/>
      </geometry>
      <material name="yellow">
        <color rgba="0 1 1 1"/>
      </material>
    </collision>
    <collision>
      <origin rpy="0 0 0" xyz="0 0 0.02"/>
      <geometry>
        <cylinder length="0.04" radius="0.008"/>
      </geometry>
      <material name="yellow"/>
    </collision>
    <collision>
      <origin rpy="0 1.57079632679 0" xyz="0 -0.00407 0.042"/>
      <geometry>
        <cylinder length="0.02" radius="0.014"/>
      </geometry>
      <material name="yellow">
        <color rgba="0 1 1 1"/>
      </material>
    </collision>
    <collision>
      <!--<origin xyz="0 -0.00407 0.04983" rpy="0.4 0 0"/>-->
      <origin rpy="0.4 0 0" xyz="0.001 -0.00207 0.06783 "/>
      <geometry>
        <cylinder length="0.05" radius="0.008"/>
      </geometry>
      <material name="yellow"/>
    </collision>
    <!-- WARNING: INERTIA NOT CORRECT -->
    <inertial>
      <origin rpy="0 0 0" xyz="-0.0002 0.92e-03 21.11e-03"/>
      <mass value="0.1"/>
      <inertia ixx="21.39e-06" ixy="3.9e-07" ixz="-7.1e-07" iyy="18.98e-06" iyz="-1.36e-06" izz="4.73e-06"/>
    </inertial>
  </link>
  <gazebo reference="l_f0_link_0">
    <mu1>1.1</mu1>
    <mu2>1.1</mu2>
    <kp>1000000.0</kp>
    <kd>10.0</kd>
    <maxVel>0.1</maxVel>
    <minDepth>0.00</minDepth>
    <maxContacts>1</maxContacts>
  </gazebo>
  <!--    <link name="${prefix}_link_1">
      <visual>
        <origin xyz="0 0 0" rpy="0 0 0"/>
        <geometry>
          <mesh filename="package://thor_vt_hand_description/meshes/collision/${prefix}_link_1.stl"/>
        </geometry>
        <material name="green"/>
      </visual>
      <collision>
        <origin xyz="-0.002 0.007 0.018" rpy="0 0 0"/>
        <geometry>
          <cylinder length="0.05" radius="0.008"/>
        </geometry>
        <material name="yellow"/>
      </collision>
    </link>-->
  <!--    <gazebo reference="${prefix}_link_1">
      <mu1>1.1</mu1>
      <mu2>1.1</mu2>
      <kp>1000000.0</kp>
      <kd>10.0</kd>
      <maxVel>0.1</maxVel>
      <minDepth>0.00</minDepth>
      <maxContacts>1</maxContacts>

    </gazebo>-->
  <!-- end of link list -->
  <!-- joint list -->
  <!-- WARNING: UPPER LIMIT NOT CORRECT/IGNORED WHILE USING MIMIC JOINT TYPE -->
  <!--		
                <joint name="${prefix}_j1" type="revolute">
                        <parent link="${prefix}_link_0"/>
                        <child link="${prefix}_link_1"/>
                        <axis xyz="1 0 0"/>
                        <origin xyz="0 -0.00407 0.04983" rpy="0.4 0 0"/>
                        <limit lower="0" upper="0.8" effort="100" velocity="100"/>
                        <mimic joint="${prefix}_j0" multiplier="0.4" offset="0"/>
                </joint>
                -->
  <!--   
    <joint name="${prefix}_j1" type="fixed">
      <parent link="${prefix}_link_0"/>
      <child link="${prefix}_link_1"/>
      <axis xyz="1 0 0"/>
      <origin xyz="0 -0.00407 0.04983" rpy="0.4 0 0"/>
      <limit lower="0" upper="0.8" effort="100" velocity="100"/>
    </joint>
    -->
  <!-- end of joint list -->
  <joint name="l_vt_hand_joint" type="fixed">
    <origin rpy="0 0 -1.57079632679" xyz="0 0 0.013"/>
    <parent link="l_wrist_ft_link"/>
    <child link="l_palm"/>
  </joint>
  <!-- link list -->
  <link name="l_palm">
    <visual>
      <geometry>
        <mesh filename="package://thor_vt_hand_description/meshes/collision/l_palm.stl"/>
      </geometry>
      <material name="green">
        <color rgba="0 1 0 1"/>
      </material>
    </visual>
    <collision>
      <geometry>
        <mesh filename="package://thor_vt_hand_description/meshes/collision/l_palm.stl"/>
      </geometry>
      <material name="yellow">
        <color rgba="0 1 1 1"/>
      </material>
    </collision>
    <!-- WARNING: INERTIA NOT CORRECT -->
    <inertial>
      <origin rpy="0 0 0" xyz="-0.00344 6.49e-03 42.12e-03"/>
      <mass value="0.7"/>
      <inertia ixx="0.1e-04" ixy="0" ixz="0" iyy="0.07e-04" iyz="0" izz="0.1e-04"/>
    </inertial>
  </link>
  <gazebo reference="l_palm">
    <mu1>1.1</mu1>
    <mu2>1.1</mu2>
    <kp>1000000.0</kp>
    <kd>1.0</kd>
    <maxVel>0.1</maxVel>
    <minDepth>0.00</minDepth>
    <maxContacts>6</maxContacts>
    <!--<material>Gazebo/FlatBlack</material>-->
  </gazebo>
  <!-- end of link list -->
  <!-- joint list -->
  <joint name="l_f1_j0" type="revolute">
    <parent link="l_palm"/>
    <child link="l_f1_link_0"/>
    <axis xyz="1 0 0"/>
    <origin rpy="-1.315 0 0" xyz="-0.036 0.0361 0.0596"/>
    <limit effort="10" lower="0" upper="2.685" velocity="10"/>
    <dynamics damping="0.0" friction="0.1"/>
  </joint>
  <joint name="l_f0_j0" type="revolute">
    <parent link="l_palm"/>
    <child link="l_f0_link_0"/>
    <axis xyz="1 0 0"/>
    <origin rpy="-1.315 0 0" xyz="0.0355 0.0361 0.0596"/>
    <limit effort="10" lower="0" upper="2.685" velocity="10"/>
    <dynamics damping="0.0" friction="0.1"/>
  </joint>
  <!-- end of joint list -->
  <transmission name="l_f0_j0_transmssion">
    <type>transmission_interface/SimpleTransmission</type>
    <joint name="l_f0_j0">
      <hardwareInterface>hardware_interface/EffortJointInterface</hardwareInterface>
    </joint>
    <actuator name="l_f0_j0_motor">
      <hardwareInterface>hardware_interface/EffortJointInterface</hardwareInterface>
      <mechanicalReduction>1</mechanicalReduction>
    </actuator>
  </transmission>
  <gazebo reference="l_f0_j0">
    <implicitSpringDamper>1</implicitSpringDamper>
  </gazebo>
  <transmission name="l_f1_j0_transmssion">
    <type>transmission_interface/SimpleTransmission</type>
    <joint name="l_f1_j0">
      <hardwareInterface>hardware_interface/EffortJointInterface</hardwareInterface>
    </joint>
    <actuator name="l_f1_j0_motor">
      <hardwareInterface>hardware_interface/EffortJointInterface</hardwareInterface>
      <mechanicalReduction>1</mechanicalReduction>
    </actuator>
  </transmission>
  <gazebo reference="l_f1_j0">
    <implicitSpringDamper>1</implicitSpringDamper>
  </gazebo>
  <!--gazebo>
    <plugin name="gazebo_ros_control" filename="libgazebo_ros_control.so">
      <robotNamespace>thor_mang</robotNamespace>
      <robotSimType>gazebo_ros_control/VT_Hand_HWSim</robotSimType>
    </plugin>
  </gazebo-->
  <!-- link list -->
  <link name="r_f1_link_0">
    <visual>
      <origin rpy="0 0 0" xyz="0 0 0"/>
      <geometry>
        <mesh filename="package://thor_vt_hand_description/meshes/collision/r_f1_link_0.stl"/>
      </geometry>
      <material name="green">
        <color rgba="0 1 0 1"/>
      </material>
    </visual>
    <visual>
      <origin rpy="0.4 0 0" xyz="0 -0.00407 0.04983"/>
      <geometry>
        <mesh filename="package://thor_vt_hand_description/meshes/collision/r_f1_link_1.stl"/>
      </geometry>
      <material name="green"/>
    </visual>
    <collision>
      <origin rpy="0 1.57079632679 0" xyz="0 0 0"/>
      <geometry>
        <cylinder length="0.02" radius="0.017"/>
      </geometry>
      <material name="yellow">
        <color rgba="0 1 1 1"/>
      </material>
    </collision>
    <collision>
      <origin rpy="0 0 0" xyz="0 0 0.02"/>
      <geometry>
        <cylinder length="0.04" radius="0.008"/>
      </geometry>
      <material name="yellow"/>
    </collision>
    <collision>
      <origin rpy="0 1.57079632679 0" xyz="0 -0.00407 0.042"/>
      <geometry>
        <cylinder length="0.02" radius="0.014"/>
      </geometry>
      <material name="yellow">
        <color rgba="0 1 1 1"/>
      </material>
    </collision>
    <collision>
      <!--<origin xyz="0 -0.00407 0.04983" rpy="0.4 0 0"/>-->
      <origin rpy="0.4 0 0" xyz="0.001 -0.00207 0.06783 "/>
      <geometry>
        <cylinder length="0.05" radius="0.008"/>
      </geometry>
      <material name="yellow"/>
    </collision>
    <!-- WARNING: INERTIA NOT CORRECT -->
    <inertial>
      <origin rpy="0 0 0" xyz="-0.0002 0.92e-03 21.11e-03"/>
      <mass value="0.1"/>
      <inertia ixx="21.39e-06" ixy="3.9e-07" ixz="-7.1e-07" iyy="18.98e-06" iyz="-1.36e-06" izz="4.73e-06"/>
    </inertial>
  </link>
  <gazebo reference="r_f1_link_0">
    <mu1>1.1</mu1>
    <mu2>1.1</mu2>
    <kp>1000000.0</kp>
    <kd>10.0</kd>
    <maxVel>0.1</maxVel>
    <minDepth>0.00</minDepth>
    <maxContacts>1</maxContacts>
  </gazebo>
  <!--    <link name="${prefix}_link_1">
      <visual>
        <origin xyz="0 0 0" rpy="0 0 0"/>
        <geometry>
          <mesh filename="package://thor_vt_hand_description/meshes/collision/${prefix}_link_1.stl"/>
        </geometry>
        <material name="green"/>
      </visual>
      <collision>
        <origin xyz="-0.002 0.007 0.018" rpy="0 0 0"/>
        <geometry>
          <cylinder length="0.05" radius="0.008"/>
        </geometry>
        <material name="yellow"/>
      </collision>
    </link>-->
  <!--    <gazebo reference="${prefix}_link_1">
      <mu1>1.1</mu1>
      <mu2>1.1</mu2>
      <kp>1000000.0</kp>
      <kd>10.0</kd>
      <maxVel>0.1</maxVel>
      <minDepth>0.00</minDepth>
      <maxContacts>1</maxContacts>

    </gazebo>-->
  <!-- end of link list -->
  <!-- joint list -->
  <!-- WARNING: UPPER LIMIT NOT CORRECT/IGNORED WHILE USING MIMIC JOINT TYPE -->
  <!--		
                <joint name="${prefix}_j1" type="revolute">
                        <parent link="${prefix}_link_0"/>
                        <child link="${prefix}_link_1"/>
                        <axis xyz="1 0 0"/>
                        <origin xyz="0 -0.00407 0.04983" rpy="0.4 0 0"/>
                        <limit lower="0" upper="0.8" effort="100" velocity="100"/>
                        <mimic joint="${prefix}_j0" multiplier="0.4" offset="0"/>
                </joint>
                -->
  <!--   
    <joint name="${prefix}_j1" type="fixed">
      <parent link="${prefix}_link_0"/>
      <child link="${prefix}_link_1"/>
      <axis xyz="1 0 0"/>
      <origin xyz="0 -0.00407 0.04983" rpy="0.4 0 0"/>
      <limit lower="0" upper="0.8" effort="100" velocity="100"/>
    </joint>
    -->
  <!-- end of joint list -->
  <!-- link list -->
  <link name="r_f0_link_0">
    <visual>
      <origin rpy="0 0 0" xyz="0 0 0"/>
      <geometry>
        <mesh filename="package://thor_vt_hand_description/meshes/collision/r_f0_link_0.stl"/>
      </geometry>
      <material name="green">
        <color rgba="0 1 0 1"/>
      </material>
    </visual>
    <visual>
      <origin rpy="0.4 0 0" xyz="0 -0.00407 0.04983"/>
      <geometry>
        <mesh filename="package://thor_vt_hand_description/meshes/collision/r_f0_link_1.stl"/>
      </geometry>
      <material name="green"/>
    </visual>
    <collision>
      <origin rpy="0 1.57079632679 0" xyz="0 0 0"/>
      <geometry>
        <cylinder length="0.02" radius="0.017"/>
      </geometry>
      <material name="yellow">
        <color rgba="0 1 1 1"/>
      </material>
    </collision>
    <collision>
      <origin rpy="0 0 0" xyz="0 0 0.02"/>
      <geometry>
        <cylinder length="0.04" radius="0.008"/>
      </geometry>
      <material name="yellow"/>
    </collision>
    <collision>
      <origin rpy="0 1.57079632679 0" xyz="0 -0.00407 0.042"/>
      <geometry>
        <cylinder length="0.02" radius="0.014"/>
      </geometry>
      <material name="yellow">
        <color rgba="0 1 1 1"/>
      </material>
    </collision>
    <collision>
      <!--<origin xyz="0 -0.00407 0.04983" rpy="0.4 0 0"/>-->
      <origin rpy="0.4 0 0" xyz="0.001 -0.00207 0.06783 "/>
      <geometry>
        <cylinder length="0.05" radius="0.008"/>
      </geometry>
      <material name="yellow"/>
    </collision>
    <!-- WARNING: INERTIA NOT CORRECT -->
    <inertial>
      <origin rpy="0 0 0" xyz="0.0002 0.92e-03 21.11e-03"/>
      <mass value="0.1"/>
      <inertia ixx="21.39e-06" ixy="-3.9e-07" ixz="7.1e-07" iyy="18.98e-06" iyz="-1.36e-06" izz="4.73e-06"/>
    </inertial>
  </link>
  <gazebo reference="r_f0_link_0">
    <mu1>1.1</mu1>
    <mu2>1.1</mu2>
    <kp>1000000.0</kp>
    <kd>10.0</kd>
    <maxVel>0.1</maxVel>
    <minDepth>0.00</minDepth>
    <maxContacts>1</maxContacts>
  </gazebo>
  <!--    <link name="${prefix}_link_1">
      <visual>
        <origin xyz="0 0 0" rpy="0 0 0"/>
        <geometry>
          <mesh filename="package://thor_vt_hand_description/meshes/collision/${prefix}_link_1.stl"/>
        </geometry>
        <material name="green"/>
      </visual>
      <collision>
        <origin xyz="-0.002 0.007 0.018" rpy="0 0 0"/>
        <geometry>
          <cylinder length="0.05" radius="0.008"/>
        </geometry>
        <material name="yellow"/>
      </collision>
    </link>-->
  <!--    <gazebo reference="${prefix}_link_1">
      <mu1>1.1</mu1>
      <mu2>1.1</mu2>
      <kp>1000000.0</kp>
      <kd>10.0</kd>
      <maxVel>0.1</maxVel>
      <minDepth>0.00</minDepth>
      <maxContacts>1</maxContacts>

    </gazebo>-->
  <!-- end of link list -->
  <!-- joint list -->
  <!-- WARNING: UPPER LIMIT NOT CORRECT/IGNORED WHILE USING MIMIC JOINT TYPE -->
  <!--		
                <joint name="${prefix}_j1" type="revolute">
                        <parent link="${prefix}_link_0"/>
                        <child link="${prefix}_link_1"/>
                        <axis xyz="1 0 0"/>
                        <origin xyz="0 -0.00407 0.04983" rpy="0.4 0 0"/>
                        <limit lower="0" upper="0.8" effort="100" velocity="100"/>
                        <mimic joint="${prefix}_j0" multiplier="0.4" offset="0"/>
                </joint>
                -->
  <!--   
    <joint name="${prefix}_j1" type="fixed">
      <parent link="${prefix}_link_0"/>
      <child link="${prefix}_link_1"/>
      <axis xyz="1 0 0"/>
      <origin xyz="0 -0.00407 0.04983" rpy="0.4 0 0"/>
      <limit lower="0" upper="0.8" effort="100" velocity="100"/>
    </joint>
    -->
  <!-- end of joint list -->
  <joint name="r_vt_hand_joint" type="fixed">
    <origin rpy="0 0 -1.57079632679" xyz="0 0 0.013"/>
    <parent link="r_wrist_ft_link"/>
    <child link="r_palm"/>
  </joint>
  <!-- link list -->
  <link name="r_palm">
    <visual>
      <geometry>
        <mesh filename="package://thor_vt_hand_description/meshes/collision/r_palm.stl"/>
      </geometry>
      <material name="green">
        <color rgba="0 1 0 1"/>
      </material>
    </visual>
    <collision>
      <geometry>
        <mesh filename="package://thor_vt_hand_description/meshes/collision/r_palm.stl"/>
      </geometry>
      <material name="yellow">
        <color rgba="0 1 1 1"/>
      </material>
    </collision>
    <!-- WARNING: INERTIA NOT CORRECT -->
    <inertial>
      <origin rpy="0 0 0" xyz="0.00344 6.49e-03 42.12e-03"/>
      <mass value="0.7"/>
      <inertia ixx="0.1e-04" ixy="0" ixz="0" iyy="0.07e-04" iyz="0" izz="0.1e-04"/>
    </inertial>
  </link>
  <gazebo reference="r_palm">
    <mu1>1.1</mu1>
    <mu2>1.1</mu2>
    <kp>1000000.0</kp>
    <kd>1.0</kd>
    <maxVel>0.1</maxVel>
    <minDepth>0.00</minDepth>
    <maxContacts>6</maxContacts>
    <!--<material>Gazebo/FlatBlack</material>-->
  </gazebo>
  <!-- end of link list -->
  <!-- joint list -->
  <joint name="r_f1_j0" type="revolute">
    <parent link="r_palm"/>
    <child link="r_f1_link_0"/>
    <axis xyz="1 0 0"/>
    <origin rpy="-1.315 0 0" xyz="0.036 0.0361 0.0596"/>
    <limit effort="10" lower="0" upper="2.685" velocity="10"/>
    <dynamics damping="0.0" friction="0.1"/>
  </joint>
  <joint name="r_f0_j0" type="revolute">
    <parent link="r_palm"/>
    <child link="r_f0_link_0"/>
    <axis xyz="1 0 0"/>
    <origin rpy="-1.315 0 0" xyz="-0.0355 0.0361 0.0596"/>
    <limit effort="10" lower="0" upper="2.685" velocity="10"/>
    <dynamics damping="0.0" friction="0.1"/>
  </joint>
  <!-- end of joint list -->
  <transmission name="r_f0_j0_transmssion">
    <type>transmission_interface/SimpleTransmission</type>
    <joint name="r_f0_j0">
      <hardwareInterface>hardware_interface/EffortJointInterface</hardwareInterface>
    </joint>
    <actuator name="r_f0_j0_motor">
      <hardwareInterface>hardware_interface/EffortJointInterface</hardwareInterface>
      <mechanicalReduction>1</mechanicalReduction>
    </actuator>
  </transmission>
  <gazebo reference="r_f0_j0">
    <implicitSpringDamper>1</implicitSpringDamper>
  </gazebo>
  <transmission name="r_f1_j0_transmssion">
    <type>transmission_interface/SimpleTransmission</type>
    <joint name="r_f1_j0">
      <hardwareInterface>hardware_interface/EffortJointInterface</hardwareInterface>
    </joint>
    <actuator name="r_f1_j0_motor">
      <hardwareInterface>hardware_interface/EffortJointInterface</hardwareInterface>
      <mechanicalReduction>1</mechanicalReduction>
    </actuator>
  </transmission>
  <gazebo reference="r_f1_j0">
    <implicitSpringDamper>1</implicitSpringDamper>
  </gazebo>
  <!--gazebo>
    <plugin name="gazebo_ros_control" filename="libgazebo_ros_control.so">
      <robotNamespace>thor_mang</robotNamespace>
      <robotSimType>gazebo_ros_control/VT_Hand_HWSim</robotSimType>
    </plugin>
  </gazebo-->
  <!-- pelvis_link -->
  <link name="pelvis_link">
    <collision>
      <origin rpy="0 0 0" xyz="-0.01 0 0.07"/>
      <geometry>
        <box size="0.2 0.25 0.17"/>
      </geometry>
    </collision>
    <visual>
      <origin rpy="0 0 0" xyz="0 0 0"/>
      <geometry>
        <mesh filename="package://thormang3_description/meshes/robotis_pelvis_link.stl" scale="0.001 0.001 0.001"/>
      </geometry>
      <material name="grey"/>
    </visual>
    <inertial>
      <origin rpy="0 0 0" xyz="-0.011 0.000 0.058"/>
      <mass value="6.869"/>
      <inertia ixx="1.0" ixy="0.0" ixz="0.0" iyy="1.0" iyz="0.0" izz="1.0"/>
      <!--<inertia ixx="0.03603" ixy="0.0" ixz="0.00016" iyy="0.02210" iyz="0.0" izz="0.03830" />-->
    </inertial>
  </link>
  <!-- torso yaw joint -->
  <joint name="torso_y" type="revolute">
    <parent link="pelvis_link"/>
    <child link="chest_link"/>
    <origin rpy="0 0 0" xyz="0 0 0.1705"/>
    <axis xyz="0 0 1"/>
    <limit effort="1000" lower="-0.785398163397" upper="0.785398163397" velocity="6.5"/>
    <dynamics damping="0.1" friction="0.0"/>
  </joint>
  <transmission name="torso_y_tran">
    <type>transmission_interface/SimpleTransmission</type>
    <joint name="torso_y">
      <hardwareInterface>hardware_interface/EffortJointInterface</hardwareInterface>
    </joint>
    <actuator name="torso_y_motor">
      <hardwareInterface>hardware_interface/EffortJointInterface</hardwareInterface>
      <mechanicalReduction>1</mechanicalReduction>
    </actuator>
  </transmission>
  <!-- chest_link -->
  <link name="chest_link">
    <collision>
      <origin rpy="0 0 0" xyz="-0.045 0 0.1"/>
      <geometry>
        <box size="0.15 0.25 0.20"/>
      </geometry>
    </collision>
    <collision>
      <origin rpy="0 0 0" xyz="0 0 0.077"/>
      <geometry>
        <box size="0.2 0.2 0.15"/>
      </geometry>
    </collision>
    <collision>
      <origin rpy="0 0 0" xyz="0 0 0.077"/>
      <geometry>
        <box size="0.2 0.2 0.15"/>
      </geometry>
    </collision>
    <collision>
      <origin rpy="0 0 0" xyz="0 -0.115 0.16"/>
      <geometry>
        <box size="0.064 0.126 0.064"/>
      </geometry>
    </collision>
    <collision>
      <origin rpy="0 0 0" xyz="0 0.115 0.16"/>
      <geometry>
        <box size="0.064 0.126 0.064"/>
      </geometry>
    </collision>
    <collision>
      <origin rpy="0 0 0" xyz="0 0.0 0.2125"/>
      <geometry>
        <box size="0.064 0.064 0.03"/>
      </geometry>
    </collision>
    <!-- left handle bar -->
    <collision>
      <origin rpy="0 0 0" xyz="-0.0375 0.135 0.155"/>
      <geometry>
        <box size="0.285 0.025 0.14"/>
      </geometry>
      <material name="grey"/>
    </collision>
    <!-- right handle bar -->
    <collision>
      <origin rpy="0 0 0" xyz="-0.0375 -0.135 0.155"/>
      <geometry>
        <box size="0.285 0.025 0.14"/>
      </geometry>
      <material name="grey"/>
    </collision>
    <visual>
      <origin rpy="0 0 0" xyz="0 0 0"/>
      <geometry>
        <mesh filename="package://thormang3_description/meshes/robotis_chest_link.stl" scale="0.001 0.001 0.001"/>
      </geometry>
      <material name="grey"/>
    </visual>
    <!-- left handle bar -->
    <visual>
      <origin rpy="0 0 0" xyz="0.095 0.135 0.155"/>
      <geometry>
        <box size="0.02 0.025 0.14"/>
      </geometry>
      <material name="grey"/>
    </visual>
    <visual>
      <origin rpy="0 0 0" xyz="-0.17 0.135 0.155"/>
      <geometry>
        <box size="0.02 0.025 0.14"/>
      </geometry>
      <material name="grey"/>
    </visual>
    <visual>
      <origin rpy="0 1.57079632679 0" xyz="-0.0375 0.135 0.215"/>
      <geometry>
        <cylinder length="0.275" radius="0.01"/>
      </geometry>
      <material name="grey"/>
    </visual>
    <visual>
      <origin rpy="0 1.57079632679 0" xyz="-0.0375 0.135 0.095"/>
      <geometry>
        <cylinder length="0.275" radius="0.01"/>
      </geometry>
      <material name="grey"/>
    </visual>
    <!-- right handle bar -->
    <visual>
      <origin rpy="0 0 0" xyz="0.095 -0.135 0.155"/>
      <geometry>
        <box size="0.02 0.025 0.14"/>
      </geometry>
      <material name="grey"/>
    </visual>
    <visual>
      <origin rpy="0 0 0" xyz="-0.17 -0.135 0.155"/>
      <geometry>
        <box size="0.02 0.025 0.14"/>
      </geometry>
      <material name="grey"/>
    </visual>
    <visual>
      <origin rpy="0 1.57079632679 0" xyz="-0.0375 -0.135 0.215"/>
      <geometry>
        <cylinder length="0.275" radius="0.01"/>
      </geometry>
      <material name="grey"/>
    </visual>
    <visual>
      <origin rpy="0 1.57079632679 0" xyz="-0.0375 -0.135 0.095"/>
      <geometry>
        <cylinder length="0.275" radius="0.01"/>
      </geometry>
      <material name="grey"/>
    </visual>
    <inertial>
      <origin rpy="0 0 0" xyz="-0.007 0.000 0.109"/>
      <mass value="5.383"/>
      <inertia ixx="1.0" ixy="0.0" ixz="0.0" iyy="1.0" iyz="0.0" izz="1.0"/>
      <inertia ixx="0.04710" ixy="0.0" ixz="0.04710" iyy="0.02554" iyz="0.0" izz="0.03094"/>
    </inertial>
  </link>
  <!-- imu joint -->
  <joint name="imu_fixed" type="fixed">
    <parent link="pelvis_link"/>
    <child link="imu_link"/>
    <origin rpy="0.0 0.0 3.14159265359" xyz="0.03 0.0 0.0"/>
  </joint>
  <link name="imu_link">
  </link>
  <!-- shoulder pitch 1 joint -->
  <joint name="l_arm_sh_p1" type="revolute">
    <axis xyz="0 1 0"/>
    <origin rpy="0 0 0" xyz="0.0 0.177 0.16"/>
    <parent link="chest_link"/>
    <child link="l_arm_sh_p1_link"/>
    <limit effort="1000" lower="-3.14159265359" upper="1.57079632679" velocity="6.5"/>
    <dynamics damping="0.1" friction="0.0"/>
  </joint>
  <transmission name="l_arm_sh_p1_tran">
    <type>transmission_interface/SimpleTransmission</type>
    <joint name="l_arm_sh_p1">
      <hardwareInterface>hardware_interface/EffortJointInterface</hardwareInterface>
    </joint>
    <actuator name="l_arm_sh_p1_motor">
      <hardwareInterface>hardware_interface/EffortJointInterface</hardwareInterface>
      <mechanicalReduction>1</mechanicalReduction>
    </actuator>
  </transmission>
  <!-- shoulder pitch 1 link -->
  <link name="l_arm_sh_p1_link">
    <collision>
      <origin rpy="0 0 0" xyz="-0.005 0.015 0"/>
      <geometry>
        <box size="0.14 0.03 0.06"/>
      </geometry>
    </collision>
    <collision>
      <origin rpy="-0.8 0 0" xyz="0.06 0.04 -0.02"/>
      <geometry>
        <box size="0.02 0.1 0.05"/>
      </geometry>
    </collision>
    <collision>
      <origin rpy="-0.8 0 0" xyz="-0.06 0.04 -0.02"/>
      <geometry>
        <box size="0.02 0.1 0.05"/>
      </geometry>
    </collision>
    <visual>
      <origin rpy="0 0 0" xyz="0 0 0"/>
      <geometry>
        <mesh filename="package://thormang3_description/meshes/robotis_l_arm_sh_p1_link.stl" scale="0.001 0.001 0.001"/>
      </geometry>
      <material name="grey"/>
    </visual>
    <inertial>
      <origin rpy="0 0 0" xyz="-0.003 0.02 -0.005"/>
      <mass value="0.194"/>
      <inertia ixx="1.0" ixy="0.0" ixz="0.0" iyy="1.0" iyz="0.0" izz="1.0"/>
      <!--<inertia ixx="0.00018" ixy="0.0" ixz="0.0" iyy="0.00058" iyz="0.00004" izz="0.00057" />-->
    </inertial>
  </link>
  <!-- shoulder roll joint -->
  <joint name="l_arm_sh_r" type="revolute">
    <axis xyz="-1 0 0"/>
    <origin rpy="0 0 0" xyz="0.057 0.06 -0.039"/>
    <parent link="l_arm_sh_p1_link"/>
    <child link="l_arm_sh_r_link"/>
    <limit effort="1000" lower="-1.16" upper="2.35619449019" velocity="6.5"/>
    <dynamics damping="0.1" friction="0.0"/>
  </joint>
  <transmission name="l_arm_sh_r_tran">
    <type>transmission_interface/SimpleTransmission</type>
    <joint name="l_arm_sh_r">
      <hardwareInterface>hardware_interface/EffortJointInterface</hardwareInterface>
    </joint>
    <actuator name="l_arm_sh_r_motor">
      <hardwareInterface>hardware_interface/EffortJointInterface</hardwareInterface>
      <mechanicalReduction>1</mechanicalReduction>
    </actuator>
  </transmission>
  <!-- shoulder roll link -->
  <link name="l_arm_sh_r_link">
    <collision>
      <origin rpy="0 0 0" xyz="-0.055 0.0 0.0"/>
      <geometry>
        <box size="0.11 0.06 0.06"/>
      </geometry>
    </collision>
    <visual>
      <origin rpy="0 0 0" xyz="0 0 0"/>
      <geometry>
        <mesh filename="package://thormang3_description/meshes/robotis_l_arm_sh_r_link.stl" scale="0.001 0.001 0.001"/>
      </geometry>
      <material name="grey"/>
    </visual>
    <inertial>
      <origin rpy="0 0 0" xyz="-0.060 0.002 0.000"/>
      <mass value="0.875"/>
      <inertia ixx="1.0" ixy="0.0" ixz="0.0" iyy="1.0" iyz="0.0" izz="1.0"/>
      <!--<inertia ixx="0.00043" ixy="0.0" ixz="0.0" iyy="0.00112" iyz="0.0" izz="0.00113" />-->
    </inertial>
  </link>
  <!-- shoulder pitch 2 joint -->
  <joint name="l_arm_sh_p2" type="revolute">
    <axis xyz="0 1 0"/>
    <origin rpy="0 0 0" xyz="-0.057 0.033 0.0"/>
    <parent link="l_arm_sh_r_link"/>
    <child link="l_arm_sh_p2_link"/>
    <limit effort="1000" lower="-3.14059265359" upper="3.14059265359" velocity="6.5"/>
    <dynamics damping="0.1" friction="0.0"/>
  </joint>
  <transmission name="l_arm_sh_p2_tran">
    <type>transmission_interface/SimpleTransmission</type>
    <joint name="l_arm_sh_p2">
      <hardwareInterface>hardware_interface/EffortJointInterface</hardwareInterface>
    </joint>
    <actuator name="l_arm_sh_p2_motor">
      <hardwareInterface>hardware_interface/EffortJointInterface</hardwareInterface>
      <mechanicalReduction>1</mechanicalReduction>
    </actuator>
  </transmission>
  <!-- shoulder pitch2 link -->
  <link name="l_arm_sh_p2_link">
    <collision>
      <origin rpy="0 0 0" xyz="0.0 0.075 0.0"/>
      <geometry>
        <box size="0.06 0.14 0.11"/>
      </geometry>
    </collision>
    <collision>
      <origin rpy="0 -1.57079632679  0" xyz="0 0.145 0"/>
      <geometry>
        <box size="0.14 0.03 0.06"/>
      </geometry>
    </collision>
    <collision>
      <origin rpy="-0.8 -1.57079632679 0" xyz="0.015 0.175 -0.06"/>
      <geometry>
        <box size="0.02 0.1 0.05"/>
      </geometry>
    </collision>
    <collision>
      <origin rpy="-0.8 -1.57079632679 0" xyz="0.015 0.175 0.06"/>
      <geometry>
        <box size="0.02 0.1 0.05"/>
      </geometry>
    </collision>
    <visual>
      <origin rpy="0 0 0" xyz="0 0 0"/>
      <geometry>
        <mesh filename="package://thormang3_description/meshes/robotis_l_arm_sh_p2_link.stl" scale="0.001 0.001 0.001"/>
      </geometry>
      <material name="grey"/>
    </visual>
    <inertial>
      <origin rpy="0 0 0" xyz="0.000 0.073 0.000"/>
      <mass value="1.122"/>
      <inertia ixx="1.0" ixy="0.0" ixz="0.0" iyy="1.0" iyz="0.0" izz="1.0"/>
      <!--<inertia ixx="0.00277" ixy="-0.00002" ixz="-0.00001" iyy="0.00090" iyz="-0.00004" izz="0.00255" />-->
    </inertial>
  </link>
  <!-- elbow yaw joint -->
  <joint name="l_arm_el_y" type="revolute">
    <axis xyz="0 0 -1"/>
    <origin rpy="0 0 0" xyz="0.030 0.187 0.057"/>
    <parent link="l_arm_sh_p2_link"/>
    <child link="l_arm_el_y_link"/>
    <limit effort="1000" lower="-1.25663706144" upper="1.25663706144" velocity="6.5"/>
    <dynamics damping="0.1" friction="0.0"/>
  </joint>
  <transmission name="l_arm_el_y_tran">
    <type>transmission_interface/SimpleTransmission</type>
    <joint name="l_arm_el_y">
      <hardwareInterface>hardware_interface/EffortJointInterface</hardwareInterface>
    </joint>
    <actuator name="l_arm_el_y_motor">
      <hardwareInterface>hardware_interface/EffortJointInterface</hardwareInterface>
      <mechanicalReduction>1</mechanicalReduction>
    </actuator>
  </transmission>
  <!-- elbow yaw link -->
  <link name="l_arm_el_y_link">
    <collision>
      <origin rpy="1.57079632679 0 0.785398163397" xyz="0.0 0.0 -0.06"/>
      <geometry>
        <box size="0.06 0.12 0.06"/>
      </geometry>
    </collision>
    <collision>
      <origin rpy="0 0 0" xyz="0.08 0.03 -0.0575"/>
      <geometry>
        <box size="0.17 0.06 0.06"/>
      </geometry>
    </collision>
    <visual>
      <origin rpy="0 0 0" xyz="0 0 0"/>
      <geometry>
        <mesh filename="package://thormang3_description/meshes/robotis_l_arm_el_y_link.stl" scale="0.001 0.001 0.001"/>
      </geometry>
      <material name="grey"/>
    </visual>
    <inertial>
      <origin rpy="0 0 0" xyz="0.042 0.012 -0.058"/>
      <mass value="1.357"/>
      <inertia ixx="1.0" ixy="0.0" ixz="0.0" iyy="1.0" iyz="0.0" izz="1.0"/>
      <!--<inertia ixx="0.00152" ixy="-0.00100" ixz="-0.00006" iyy="0.00560" iyz="-0.00002" izz="0.00528" />-->
    </inertial>
  </link>
  <!-- wrist roll joint -->
  <joint name="l_arm_wr_r" type="revolute">
    <axis xyz="1 0 0"/>
    <origin rpy="0 0 0" xyz="0.171 0.03 -0.057"/>
    <parent link="l_arm_el_y_link"/>
    <child link="l_arm_wr_r_link"/>
    <limit effort="1000" lower="-2.82743338823" upper="2.82743338823" velocity="6.5"/>
    <dynamics damping="0.1" friction="0.0"/>
  </joint>
  <transmission name="l_arm_wr_r_tran">
    <type>transmission_interface/SimpleTransmission</type>
    <joint name="l_arm_wr_r">
      <hardwareInterface>hardware_interface/EffortJointInterface</hardwareInterface>
    </joint>
    <actuator name="l_arm_wr_r_motor">
      <hardwareInterface>hardware_interface/EffortJointInterface</hardwareInterface>
      <mechanicalReduction>1</mechanicalReduction>
    </actuator>
  </transmission>
  <!-- wrist roll link -->
  <link name="l_arm_wr_r_link">
    <collision>
      <origin rpy="0 0 0" xyz="0 0 0"/>
      <geometry>
        <mesh filename="package://thormang3_description/meshes/robotis_l_arm_wr_r_link.stl" scale="0.001 0.001 0.001"/>
      </geometry>
    </collision>
    <collision>
      <origin rpy="-1.57079632679 0 0 " xyz="0.01 0.0 0.0"/>
      <geometry>
        <box size="0.02 0.1 0.05"/>
      </geometry>
    </collision>
    <collision>
      <origin rpy="0 0 0 " xyz="0.0325 0.0 0.05"/>
      <geometry>
        <box size="0.065 0.05 0.01"/>
      </geometry>
    </collision>
    <collision>
      <origin rpy="0 0 0 " xyz="0.0325 0.0 -0.05"/>
      <geometry>
        <box size="0.065 0.05 0.01"/>
      </geometry>
    </collision>
    <visual>
      <origin rpy="0 0 0" xyz="0 0 0"/>
      <geometry>
        <mesh filename="package://thormang3_description/meshes/robotis_l_arm_wr_r_link.stl" scale="0.001 0.001 0.001"/>
      </geometry>
      <material name="grey"/>
    </visual>
    <inertial>
      <origin rpy="0 0 0" xyz="0.010 0.000 0.002"/>
      <mass value="0.087"/>
      <inertia ixx="1.0" ixy="0.0" ixz="0.0" iyy="1.0" iyz="0.0" izz="1.0"/>
      <!--<inertia ixx="0.00012" ixy="0.0" ixz="0.0" iyy="0.00011" iyz="0.0" izz="0.00003" />-->
    </inertial>
  </link>
  <!-- wrist yaw joint -->
  <joint name="l_arm_wr_y" type="revolute">
    <axis xyz="0 0 -1"/>
    <origin rpy="0 0 0" xyz="0.039 0.0 0.045"/>
    <parent link="l_arm_wr_r_link"/>
    <child link="l_arm_wr_y_link"/>
    <limit effort="1000" lower="-1.41371669412" upper="1.41371669412" velocity="6.5"/>
    <dynamics damping="0.1" friction="0.0"/>
  </joint>
  <transmission name="l_arm_wr_y_tran">
    <type>transmission_interface/SimpleTransmission</type>
    <joint name="l_arm_wr_y">
      <hardwareInterface>hardware_interface/EffortJointInterface</hardwareInterface>
    </joint>
    <actuator name="l_arm_wr_y_motor">
      <hardwareInterface>hardware_interface/EffortJointInterface</hardwareInterface>
      <mechanicalReduction>1</mechanicalReduction>
    </actuator>
  </transmission>
  <!-- wrist yaw link -->
  <link name="l_arm_wr_y_link">
    <collision>
      <origin rpy="1.57079632679 0 0" xyz="0.0 0.0 -0.045"/>
      <geometry>
        <box size="0.045 0.09 0.045"/>
      </geometry>
    </collision>
    <collision>
      <origin rpy="0 0 0" xyz="0.045 0.0 -0.045"/>
      <geometry>
        <box size="0.045 0.09 0.045"/>
      </geometry>
    </collision>
    <visual>
      <origin rpy="0 0 0" xyz="0 0 0"/>
      <geometry>
        <mesh filename="package://thormang3_description/meshes/robotis_l_arm_wr_y_link.stl" scale="0.001 0.001 0.001"/>
      </geometry>
      <material name="grey"/>
    </visual>
    <inertial>
      <origin rpy="0 0 0" xyz="0.023 0.001 -0.046"/>
      <mass value="0.768"/>
      <inertia ixx="1.0" ixy="0.0" ixz="0.0" iyy="1.0" iyz="0.0" izz="1.0"/>
      <!--<inertia ixx="0.00059" ixy="-0.00002" ixz="-0.00002" iyy="0.00078" iyz="0.0" izz="0.00078" />-->
    </inertial>
  </link>
  <!-- wrist pitch joint -->
  <joint name="l_arm_wr_p" type="revolute">
    <axis xyz="0 -1 0"/>
    <origin rpy="0 0 0" xyz="0.045 -0.045 -0.045"/>
    <parent link="l_arm_wr_y_link"/>
    <child link="l_arm_wr_p_link"/>
    <limit effort="1000" lower="-1.25663706144" upper="1.25663706144" velocity="6.5"/>
    <dynamics damping="0.1" friction="0.0"/>
  </joint>
  <transmission name="l_arm_wr_p_tran">
    <type>transmission_interface/SimpleTransmission</type>
    <joint name="l_arm_wr_p">
      <hardwareInterface>hardware_interface/EffortJointInterface</hardwareInterface>
    </joint>
    <actuator name="l_arm_wr_p_motor">
      <hardwareInterface>hardware_interface/EffortJointInterface</hardwareInterface>
      <mechanicalReduction>1</mechanicalReduction>
    </actuator>
  </transmission>
  <!-- wrist pitch link -->
  <link name="l_arm_wr_p_link">
    <collision>
      <origin rpy="1.57079632679 1.57079632679 0" xyz="0.0055 0.09 0.0"/>
      <geometry>
        <box size="0.05 0.065 0.01"/>
      </geometry>
    </collision>
    <collision>
      <origin rpy="1.57079632679 1.57079632679 0" xyz="0.0055 -0.005 0.0"/>
      <geometry>
        <box size="0.05 0.065 0.01"/>
      </geometry>
    </collision>
    <collision>
      <origin rpy="0 0 0 " xyz="0.04 0.043 0.0"/>
      <geometry>
        <box size="0.02 0.105 0.05"/>
      </geometry>
    </collision>
    <visual>
      <origin rpy="1.57079632679 3.14159265359 0" xyz="0.039 0.045 0.000"/>
      <geometry>
        <mesh filename="package://thormang3_description/meshes/robotis_l_arm_wr_r_link.stl" scale="0.001 0.001 0.001"/>
      </geometry>
      <material name="grey"/>
    </visual>
    <inertial>
      <origin rpy="0 0 0" xyz="0.049 0.045 0.002"/>
      <mass value="0.087"/>
      <inertia ixx="1.0" ixy="0.0" ixz="0.0" iyy="1.0" iyz="0.0" izz="1.0"/>
      <!--<inertia ixx="0.00047" ixy="-0.00001" ixz="0.0" iyy="0.00042" iyz="0.0" izz="0.00058" />-->
    </inertial>
  </link>
  <!--ft joint -->
  <!--use "fixed" revolute joint for FT sensor simulation-->
  <joint name="l_arm_ft" type="revolute">
    <origin rpy="-1.57079632679 0 -1.57079632679" xyz="0.055 0.045 0"/>
    <parent link="l_arm_wr_p_link"/>
    <child link="l_wrist_ft_link"/>
    <limit effort="1000" lower="0" upper="0" velocity="6.5"/>
  </joint>
  <!-- wrist ft link -->
  <link name="l_wrist_ft_link">
    </link>
  <!-- shoulder pitch 1 joint -->
  <joint name="r_arm_sh_p1" type="revolute">
    <axis xyz="0 -1 0"/>
    <origin rpy="0 0 0" xyz="0.0 -0.177 0.16"/>
    <parent link="chest_link"/>
    <child link="r_arm_sh_p1_link"/>
    <limit effort="1000" lower="-1.57079632679" upper="3.14159265359" velocity="6.5"/>
    <dynamics damping="0.1" friction="0.0"/>
  </joint>
  <transmission name="r_arm_sh_p1_tran">
    <type>transmission_interface/SimpleTransmission</type>
    <joint name="r_arm_sh_p1">
      <hardwareInterface>hardware_interface/EffortJointInterface</hardwareInterface>
    </joint>
    <actuator name="r_arm_sh_p1_motor">
      <hardwareInterface>hardware_interface/EffortJointInterface</hardwareInterface>
      <mechanicalReduction>1</mechanicalReduction>
    </actuator>
  </transmission>
  <!-- shoulder pitch 1 link -->
  <link name="r_arm_sh_p1_link">
    <collision>
      <origin rpy="0 0 0" xyz="0.005 -0.015 0"/>
      <geometry>
        <box size="0.14 0.03 0.06"/>
      </geometry>
    </collision>
    <collision>
      <origin rpy="0.8 0 0" xyz="-0.06 -0.04 -0.02"/>
      <geometry>
        <box size="0.02 0.1 0.05"/>
      </geometry>
    </collision>
    <collision>
      <origin rpy="0.8 0 0" xyz="0.06 -0.04 -0.02"/>
      <geometry>
        <box size="0.02 0.1 0.05"/>
      </geometry>
    </collision>
    <visual>
      <origin rpy="0 0 0" xyz="0 0 0"/>
      <geometry>
        <mesh filename="package://thormang3_description/meshes/robotis_r_arm_sh_p1_link.stl" scale="0.001 0.001 0.001"/>
      </geometry>
      <material name="grey"/>
    </visual>
    <inertial>
      <origin rpy="0 0 0" xyz="-0.003 -0.02 -0.005"/>
      <mass value="0.194"/>
      <inertia ixx="1.0" ixy="0.0" ixz="0.0" iyy="1.0" iyz="0.0" izz="1.0"/>
      <!--<inertia ixx="0.00018" ixy="0.0" ixz="0.0" iyy="0.00058" iyz="0.00004" izz="0.00057" />-->
    </inertial>
  </link>
  <!-- shoulder roll joint -->
  <joint name="r_arm_sh_r" type="revolute">
    <axis xyz="-1 0 0"/>
    <origin rpy="0 0 0" xyz="0.057 -0.06 -0.039"/>
    <parent link="r_arm_sh_p1_link"/>
    <child link="r_arm_sh_r_link"/>
    <limit effort="1000" lower="-2.35619449019" upper="1.16" velocity="6.5"/>
    <dynamics damping="0.1" friction="0.0"/>
  </joint>
  <transmission name="r_arm_sh_r_tran">
    <type>transmission_interface/SimpleTransmission</type>
    <joint name="r_arm_sh_r">
      <hardwareInterface>hardware_interface/EffortJointInterface</hardwareInterface>
    </joint>
    <actuator name="r_arm_sh_r_motor">
      <hardwareInterface>hardware_interface/EffortJointInterface</hardwareInterface>
      <mechanicalReduction>1</mechanicalReduction>
    </actuator>
  </transmission>
  <!-- shoulder roll link -->
  <link name="r_arm_sh_r_link">
    <collision>
      <origin rpy="0 0 0" xyz="-0.055 0.0 0.0"/>
      <geometry>
        <box size="0.11 0.06 0.06"/>
      </geometry>
    </collision>
    <visual>
      <origin rpy="0 0 0" xyz="0 0 0"/>
      <geometry>
        <mesh filename="package://thormang3_description/meshes/robotis_r_arm_sh_r_link.stl" scale="0.001 0.001 0.001"/>
      </geometry>
      <material name="grey"/>
    </visual>
    <inertial>
      <origin rpy="0 0 0" xyz="-0.060 -0.002 0.000"/>
      <mass value="0.875"/>
      <inertia ixx="1.0" ixy="0.0" ixz="0.0" iyy="1.0" iyz="0.0" izz="1.0"/>
      <!--<inertia ixx="0.00043" ixy="0.0" ixz="0.0" iyy="0.00112" iyz="0.0" izz="0.00113" />-->
    </inertial>
  </link>
  <!-- shoulder pitch 2 joint -->
  <joint name="r_arm_sh_p2" type="revolute">
    <axis xyz="0 -1 0"/>
    <origin rpy="0 0 0" xyz="-0.057 -0.033 0.0"/>
    <parent link="r_arm_sh_r_link"/>
    <child link="r_arm_sh_p2_link"/>
    <limit effort="1000" lower="-3.14059265359" upper="3.14059265359" velocity="6.5"/>
    <dynamics damping="0.1" friction="0.0"/>
  </joint>
  <transmission name="r_arm_sh_p2_tran">
    <type>transmission_interface/SimpleTransmission</type>
    <joint name="r_arm_sh_p2">
      <hardwareInterface>hardware_interface/EffortJointInterface</hardwareInterface>
    </joint>
    <actuator name="r_arm_sh_p2_motor">
      <hardwareInterface>hardware_interface/EffortJointInterface</hardwareInterface>
      <mechanicalReduction>1</mechanicalReduction>
    </actuator>
  </transmission>
  <!-- shoulder pitch2 link -->
  <link name="r_arm_sh_p2_link">
    <collision>
      <origin rpy="0 0 0" xyz="0.0 -0.075 0.0"/>
      <geometry>
        <box size="0.06 0.14 0.11"/>
      </geometry>
    </collision>
    <collision>
      <origin rpy="0 -1.57079632679  0" xyz="0 -0.145 0"/>
      <geometry>
        <box size="0.14 0.03 0.06"/>
      </geometry>
    </collision>
    <collision>
      <origin rpy="0.8 -1.57079632679 0" xyz="0.015 -0.175 -0.06"/>
      <geometry>
        <box size="0.02 0.1 0.05"/>
      </geometry>
    </collision>
    <collision>
      <origin rpy="0.8 -1.57079632679 0" xyz="0.015 -0.175 0.06"/>
      <geometry>
        <box size="0.02 0.1 0.05"/>
      </geometry>
    </collision>
    <visual>
      <origin rpy="0 0 0" xyz="0 0 0"/>
      <geometry>
        <mesh filename="package://thormang3_description/meshes/robotis_r_arm_sh_p2_link.stl" scale="0.001 0.001 0.001"/>
      </geometry>
      <material name="grey"/>
    </visual>
    <inertial>
      <origin rpy="0 0 0" xyz="0.000 0.073 0.000"/>
      <mass value="1.122"/>
      <inertia ixx="1.0" ixy="0.0" ixz="0.0" iyy="1.0" iyz="0.0" izz="1.0"/>
      <!--<inertia ixx="0.00277" ixy="-0.00002" ixz="-0.00001" iyy="0.00090" iyz="-0.00004" izz="0.00255" />-->
    </inertial>
  </link>
  <!-- elbow yaw joint -->
  <joint name="r_arm_el_y" type="revolute">
    <axis xyz="0 0 -1"/>
    <origin rpy="0 0 0" xyz="0.030 -0.187 0.057"/>
    <parent link="r_arm_sh_p2_link"/>
    <child link="r_arm_el_y_link"/>
    <limit effort="1000" lower="-1.25663706144" upper="1.25663706144" velocity="6.5"/>
    <dynamics damping="0.1" friction="0.0"/>
  </joint>
  <transmission name="r_arm_el_y_tran">
    <type>transmission_interface/SimpleTransmission</type>
    <joint name="r_arm_el_y">
      <hardwareInterface>hardware_interface/EffortJointInterface</hardwareInterface>
    </joint>
    <actuator name="r_arm_el_y_motor">
      <hardwareInterface>hardware_interface/EffortJointInterface</hardwareInterface>
      <mechanicalReduction>1</mechanicalReduction>
    </actuator>
  </transmission>
  <!-- elbow yaw link -->
  <link name="r_arm_el_y_link">
    <collision>
      <origin rpy="1.57079632679 0 0.785398163397" xyz="0.0 0.0 -0.06"/>
      <geometry>
        <box size="0.06 0.12 0.06"/>
      </geometry>
    </collision>
    <collision>
      <origin rpy="0 0 0" xyz="0.08 -0.03 -0.0575"/>
      <geometry>
        <box size="0.17 0.06 0.06"/>
      </geometry>
    </collision>
    <visual>
      <origin rpy="0 0 0" xyz="0 0 0"/>
      <geometry>
        <mesh filename="package://thormang3_description/meshes/robotis_r_arm_el_y_link.stl" scale="0.001 0.001 0.001"/>
      </geometry>
      <material name="grey"/>
    </visual>
    <inertial>
      <origin rpy="0 0 0" xyz="0.042 -0.012 -0.058"/>
      <mass value="1.357"/>
      <inertia ixx="1.0" ixy="0.0" ixz="0.0" iyy="1.0" iyz="0.0" izz="1.0"/>
      <!--<inertia ixx="0.00152" ixy="-0.00100" ixz="-0.00006" iyy="0.00560" iyz="-0.00002" izz="0.00528" />-->
    </inertial>
  </link>
  <!-- wrist roll joint -->
  <joint name="r_arm_wr_r" type="revolute">
    <axis xyz="1 0 0"/>
    <origin rpy="0 0 0" xyz="0.171 -0.03 -0.057"/>
    <parent link="r_arm_el_y_link"/>
    <child link="r_arm_wr_r_link"/>
    <limit effort="1000" lower="-2.82743338823" upper="2.82743338823" velocity="6.5"/>
    <dynamics damping="0.1" friction="0.0"/>
  </joint>
  <transmission name="r_arm_wr_r_tran">
    <type>transmission_interface/SimpleTransmission</type>
    <joint name="r_arm_wr_r">
      <hardwareInterface>hardware_interface/EffortJointInterface</hardwareInterface>
    </joint>
    <actuator name="r_arm_wr_r_motor">
      <hardwareInterface>hardware_interface/EffortJointInterface</hardwareInterface>
      <mechanicalReduction>1</mechanicalReduction>
    </actuator>
  </transmission>
  <!-- wrist roll link -->
  <link name="r_arm_wr_r_link">
    <collision>
      <origin rpy="0 0 0" xyz="0 0 0"/>
      <geometry>
        <mesh filename="package://thormang3_description/meshes/robotis_r_arm_wr_r_link.stl" scale="0.001 0.001 0.001"/>
      </geometry>
    </collision>
    <collision>
      <origin rpy="-1.57079632679 0 0 " xyz="0.01 0.0 0.0"/>
      <geometry>
        <box size="0.02 0.1 0.05"/>
      </geometry>
    </collision>
    <collision>
      <origin rpy="0 0 0 " xyz="0.0325 0.0 0.05"/>
      <geometry>
        <box size="0.065 0.05 0.01"/>
      </geometry>
    </collision>
    <collision>
      <origin rpy="0 0 0 " xyz="0.0325 0.0 -0.05"/>
      <geometry>
        <box size="0.065 0.05 0.01"/>
      </geometry>
    </collision>
    <visual>
      <origin rpy="0 0 0" xyz="0 0 0"/>
      <geometry>
        <mesh filename="package://thormang3_description/meshes/robotis_r_arm_wr_r_link.stl" scale="0.001 0.001 0.001"/>
      </geometry>
      <material name="grey"/>
    </visual>
    <inertial>
      <origin rpy="0 0 0" xyz="0.010 0.000 -0.002"/>
      <mass value="0.087"/>
      <inertia ixx="1.0" ixy="0.0" ixz="0.0" iyy="1.0" iyz="0.0" izz="1.0"/>
      <!--<inertia ixx="0.00012" ixy="0.0" ixz="0.0" iyy="0.00011" iyz="0.0" izz="0.00003" />-->
    </inertial>
  </link>
  <!-- wrist yaw joint -->
  <joint name="r_arm_wr_y" type="revolute">
    <axis xyz="0 0 -1"/>
    <origin rpy="0 0 0" xyz="0.039 0.0 0.045"/>
    <parent link="r_arm_wr_r_link"/>
    <child link="r_arm_wr_y_link"/>
    <limit effort="1000" lower="-1.41371669412" upper="1.41371669412" velocity="6.5"/>
    <dynamics damping="0.1" friction="0.0"/>
  </joint>
  <transmission name="r_arm_wr_y_tran">
    <type>transmission_interface/SimpleTransmission</type>
    <joint name="r_arm_wr_y">
      <hardwareInterface>hardware_interface/EffortJointInterface</hardwareInterface>
    </joint>
    <actuator name="r_arm_wr_y_motor">
      <hardwareInterface>hardware_interface/EffortJointInterface</hardwareInterface>
      <mechanicalReduction>1</mechanicalReduction>
    </actuator>
  </transmission>
  <!-- wrist yaw link -->
  <link name="r_arm_wr_y_link">
    <collision>
      <origin rpy="1.57079632679 0 0" xyz="0.0 0.0 -0.045"/>
      <geometry>
        <box size="0.045 0.09 0.045"/>
      </geometry>
    </collision>
    <collision>
      <origin rpy="0 0 0" xyz="0.045 0.0 -0.045"/>
      <geometry>
        <box size="0.045 0.09 0.045"/>
      </geometry>
    </collision>
    <visual>
      <origin rpy="0 0 0" xyz="0 0 0"/>
      <geometry>
        <mesh filename="package://thormang3_description/meshes/robotis_r_arm_wr_y_link.stl" scale="0.001 0.001 0.001"/>
      </geometry>
      <material name="grey"/>
    </visual>
    <inertial>
      <origin rpy="0 0 0" xyz="0.023 -0.001 -0.046"/>
      <mass value="0.768"/>
      <inertia ixx="1.0" ixy="0.0" ixz="0.0" iyy="1.0" iyz="0.0" izz="1.0"/>
      <!--<inertia ixx="0.00059" ixy="-0.00002" ixz="-0.00002" iyy="0.00078" iyz="0.0" izz="0.00078" />-->
    </inertial>
  </link>
  <!-- wrist pitch joint -->
  <joint name="r_arm_wr_p" type="revolute">
    <axis xyz="0 1 0"/>
    <origin rpy="0 0 0" xyz="0.045 0.045 -0.045"/>
    <parent link="r_arm_wr_y_link"/>
    <child link="r_arm_wr_p_link"/>
    <limit effort="1000" lower="-1.25663706144" upper="1.25663706144" velocity="6.5"/>
    <dynamics damping="0.1" friction="0.0"/>
  </joint>
  <transmission name="r_arm_wr_p_tran">
    <type>transmission_interface/SimpleTransmission</type>
    <joint name="r_arm_wr_p">
      <hardwareInterface>hardware_interface/EffortJointInterface</hardwareInterface>
    </joint>
    <actuator name="r_arm_wr_p_motor">
      <hardwareInterface>hardware_interface/EffortJointInterface</hardwareInterface>
      <mechanicalReduction>1</mechanicalReduction>
    </actuator>
  </transmission>
  <!-- wrist pitch link -->
  <link name="r_arm_wr_p_link">
    <collision>
      <origin rpy="1.57079632679 1.57079632679 0" xyz="0.0055 -0.09 0.0"/>
      <geometry>
        <box size="0.05 0.065 0.01"/>
      </geometry>
    </collision>
    <collision>
      <origin rpy="1.57079632679 1.57079632679 0" xyz="0.0055 0.005 0.0"/>
      <geometry>
        <box size="0.05 -0.065 0.01"/>
      </geometry>
    </collision>
    <collision>
      <origin rpy="0 0 0 " xyz="0.04 -0.043 0.0"/>
      <geometry>
        <box size="0.02 0.105 0.05"/>
      </geometry>
    </collision>
    <visual>
      <origin rpy="-1.57079632679 3.14159265359 0" xyz="0.039 -0.045 0.000"/>
      <geometry>
        <mesh filename="package://thormang3_description/meshes/robotis_r_arm_wr_r_link.stl" scale="0.001 0.001 0.001"/>
      </geometry>
      <material name="grey"/>
    </visual>
    <inertial>
      <origin rpy="0 0 0" xyz="0.049 -0.045 -0.002"/>
      <mass value="0.087"/>
      <inertia ixx="1.0" ixy="0.0" ixz="0.0" iyy="1.0" iyz="0.0" izz="1.0"/>
      <!--<inertia ixx="0.00047" ixy="-0.00001" ixz="0.0" iyy="0.00042" iyz="0.0" izz="0.00058" />-->
    </inertial>
  </link>
  <!--ft joint -->
  <!--use "fixed" revolute joint for FT sensor simulation-->
  <joint name="r_arm_ft" type="revolute">
    <origin rpy="1.57079632679 0 1.57079632679" xyz="0.055 -0.045 0"/>
    <parent link="r_arm_wr_p_link"/>
    <child link="r_wrist_ft_link"/>
    <limit effort="1000" lower="0" upper="0" velocity="6.5"/>
  </joint>
  <!-- wrist ft link -->
  <link name="r_wrist_ft_link">
    </link>
  <!-- hip yaw joint -->
  <joint name="l_leg_hip_y" type="revolute">
    <axis xyz="0 0 -1"/>
    <origin rpy="0 0 0" xyz="0.0 0.093 -0.018"/>
    <parent link="pelvis_link"/>
    <child link="l_leg_hip_y_link"/>
    <limit effort="1000" lower="-1.41371669412" upper="1.41371669412" velocity="6.5"/>
    <dynamics damping="0.1" friction="0.0"/>
  </joint>
  <transmission name="l_leg_hip_y_tran">
    <type>transmission_interface/SimpleTransmission</type>
    <joint name="l_leg_hip_y">
      <hardwareInterface>hardware_interface/EffortJointInterface</hardwareInterface>
    </joint>
    <actuator name="l_leg_hip_y_motor">
      <hardwareInterface>hardware_interface/EffortJointInterface</hardwareInterface>
      <mechanicalReduction>1</mechanicalReduction>
    </actuator>
  </transmission>
  <!-- hip yaw link -->
  <link name="l_leg_hip_y_link">
    <collision>
      <origin rpy="0 0 0" xyz="-0.01 0 -0.05"/>
      <geometry>
        <box size="0.17 0.07 0.1"/>
      </geometry>
    </collision>
    <visual>
      <origin rpy="0 0 0" xyz="0 0 0"/>
      <geometry>
        <mesh filename="package://thormang3_description/meshes/robotis_l_leg_hip_y_link.stl" scale="0.001 0.001 0.001"/>
      </geometry>
      <material name="grey"/>
    </visual>
    <inertial>
      <origin rpy="0 0 0" xyz="0.012 0.0 -0.025"/>
      <mass value="0.243"/>
      <inertia ixx="1.0" ixy="0.0" ixz="0.0" iyy="1.0" iyz="0.0" izz="1.0"/>
      <!-- <inertia ixx="0.00024" ixy="0.0" ixz="0.0" iyy="0.00101" iyz="0.0" izz="0.00092" /> -->
    </inertial>
  </link>
  <!-- hip roll joint -->
  <joint name="l_leg_hip_r" type="revolute">
    <axis xyz="-1 0 0"/>
    <origin rpy="0 0 0" xyz="0.057 0.0 -0.075"/>
    <parent link="l_leg_hip_y_link"/>
    <child link="l_leg_hip_r_link"/>
    <limit effort="1000" lower="-0.628318530718" upper="0.628318530718" velocity="6.5"/>
    <dynamics damping="0.1" friction="0.0"/>
  </joint>
  <transmission name="l_leg_hip_r_tran">
    <type>transmission_interface/SimpleTransmission</type>
    <joint name="l_leg_hip_r">
      <hardwareInterface>hardware_interface/EffortJointInterface</hardwareInterface>
    </joint>
    <actuator name="l_leg_hip_r_motor">
      <hardwareInterface>hardware_interface/EffortJointInterface</hardwareInterface>
      <mechanicalReduction>1</mechanicalReduction>
    </actuator>
  </transmission>
  <!-- hip roll link -->
  <link name="l_leg_hip_r_link">
    <!--
          <collision>
              <origin xyz="-0.057 0 0" rpy="0 0 0"/>
              <geometry>
                <box size="0.01 0.01 0.01" />
              </geometry>
          </collision>
  -->
    <visual>
      <origin rpy="0 0 0" xyz="0 0 0"/>
      <geometry>
        <mesh filename="package://thormang3_description/meshes/robotis_l_leg_hip_r_link.stl" scale="0.001 0.001 0.001"/>
      </geometry>
      <material name="grey"/>
    </visual>
    <inertial>
      <origin rpy="0 0 0" xyz="-0.068 0.0 0.000"/>
      <mass value="1.045"/>
      <inertia ixx="1.0" ixy="0.0" ixz="0.0" iyy="1.0" iyz="0.0" izz="1.0"/>
      <!-- <inertia ixx="0.00056" ixy="0.0" ixz="0.0" iyy="0.00168" iyz="0.0" izz="0.00171" /> -->
    </inertial>
  </link>
  <!-- hip pitch joint -->
  <joint name="l_leg_hip_p" type="revolute">
    <axis xyz="0 1 0"/>
    <origin rpy="0 0 0" xyz="-0.057 0.033 0.0"/>
    <parent link="l_leg_hip_r_link"/>
    <child link="l_leg_hip_p_link"/>
    <limit effort="1000" lower="-1.25663706144" upper="0.785398163397" velocity="6.5"/>
    <dynamics damping="0.1" friction="0.0"/>
  </joint>
  <transmission name="l_leg_hip_p_tran">
    <type>transmission_interface/SimpleTransmission</type>
    <joint name="l_leg_hip_p">
      <hardwareInterface>hardware_interface/EffortJointInterface</hardwareInterface>
    </joint>
    <actuator name="l_leg_hip_p_motor">
      <hardwareInterface>hardware_interface/EffortJointInterface</hardwareInterface>
      <mechanicalReduction>1</mechanicalReduction>
    </actuator>
  </transmission>
  <!-- hip pitch link -->
  <link name="l_leg_hip_p_link">
    <collision>
      <origin rpy="0 0 0" xyz="0 -0.005 -0.135"/>
      <geometry>
        <box size="0.11 0.16 0.34"/>
      </geometry>
    </collision>
    <visual>
      <origin rpy="0 0 0" xyz="0 0 0"/>
      <geometry>
        <mesh filename="package://thormang3_description/meshes/robotis_l_leg_hip_p_link.stl" scale="0.001 0.001 0.001"/>
      </geometry>
      <material name="grey"/>
    </visual>
    <inertial>
      <origin rpy="0 0 0" xyz="0.022 -0.007 -0.168"/>
      <mass value="3.095"/>
      <inertia ixx="1.0" ixy="0.0" ixz="0.0" iyy="1.0" iyz="0.0" izz="1.0"/>
      <!-- <inertia ixx="0.04328" ixy="0.00028" ixz="0.00288" iyy="0.04042" iyz="-0.00202" izz="0.00560" /> -->
    </inertial>
  </link>
  <!-- knee pitch joint -->
  <joint name="l_leg_kn_p" type="revolute">
    <axis xyz="0 1 0"/>
    <origin rpy="0 0 0" xyz="0.0 0.06 -0.3"/>
    <parent link="l_leg_hip_p_link"/>
    <child link="l_leg_kn_p_link"/>
    <limit effort="1000" lower="-1.41371669412" upper="1.88495559215" velocity="6.5"/>
    <dynamics damping="0.1" friction="0.0"/>
  </joint>
  <transmission name="l_leg_kn_p_tran">
    <type>transmission_interface/SimpleTransmission</type>
    <joint name="l_leg_kn_p">
      <hardwareInterface>hardware_interface/EffortJointInterface</hardwareInterface>
    </joint>
    <actuator name="l_leg_kn_p_motor">
      <hardwareInterface>hardware_interface/EffortJointInterface</hardwareInterface>
      <mechanicalReduction>1</mechanicalReduction>
    </actuator>
  </transmission>
  <!-- knee pitch link -->
  <link name="l_leg_kn_p_link">
    <collision>
      <origin rpy="0 0 0" xyz="0.01 -0.065 -0.145"/>
      <geometry>
        <box size="0.11 0.16 0.33"/>
      </geometry>
    </collision>
    <visual>
      <origin rpy="0 0 0" xyz="0 0 0"/>
      <geometry>
        <mesh filename="package://thormang3_description/meshes/robotis_l_leg_kn_p_link.stl" scale="0.001 0.001 0.001"/>
      </geometry>
      <material name="grey"/>
    </visual>
    <inertial>
      <origin rpy="0 0 0" xyz="-0.002 -0.066 -0.183"/>
      <mass value="2.401"/>
      <inertia ixx="1.0" ixy="0.0" ixz="0.0" iyy="1.0" iyz="0.0" izz="1.0"/>
      <!-- <inertia ixx="0.01971" ixy="0.00031" ixz="-0.00294" iyy="0.01687" iyz="0.00140" izz="0.00574" /> -->
    </inertial>
  </link>
  <!-- ankle pitch joint -->
  <joint name="l_leg_an_p" type="revolute">
    <axis xyz="0 -1 0"/>
    <origin rpy="0 0 0" xyz="0.0 -0.06 -0.3"/>
    <parent link="l_leg_kn_p_link"/>
    <child link="l_leg_an_p_link"/>
    <limit effort="1000" lower="-1.41371669412" upper="1.41371669412" velocity="6.5"/>
    <dynamics damping="0.1" friction="0.0"/>
  </joint>
  <transmission name="l_leg_an_p_tran">
    <type>transmission_interface/SimpleTransmission</type>
    <joint name="l_leg_an_p">
      <hardwareInterface>hardware_interface/EffortJointInterface</hardwareInterface>
    </joint>
    <actuator name="l_leg_an_p_motor">
      <hardwareInterface>hardware_interface/EffortJointInterface</hardwareInterface>
      <mechanicalReduction>1</mechanicalReduction>
    </actuator>
  </transmission>
  <!-- ankle pitch link -->
  <link name="l_leg_an_p_link">
    <!--
        <collision>
            <origin xyz="0 0 0" rpy="0 0 0"/>
            <geometry>
              <box size="0.01 0.01 0.01" />
            </geometry>
        </collision>
-->
    <visual>
      <origin rpy="0 0 0" xyz="0 0 0"/>
      <geometry>
        <mesh filename="package://thormang3_description/meshes/robotis_l_leg_an_p_link.stl" scale="0.001 0.001 0.001"/>
      </geometry>
      <material name="grey"/>
    </visual>
    <inertial>
      <origin rpy="0 0 0" xyz="-0.011 -0.033 0.000"/>
      <mass value="1.045"/>
      <inertia ixx="1.0" ixy="0.0" ixz="0.0" iyy="1.0" iyz="0.0" izz="1.0"/>
      <!-- <inertia ixx="0.00056" ixy="0.0" ixz="0.0" iyy="0.00168" iyz="0.0" izz="0.00171" /> -->
    </inertial>
  </link>
  <!-- ankle roll joint -->
  <joint name="l_leg_an_r" type="revolute">
    <axis xyz="1 0 0"/>
    <origin rpy="0 0 0" xyz="0.057 -0.033 0.0"/>
    <parent link="l_leg_an_p_link"/>
    <child link="l_leg_an_r_link"/>
    <limit effort="1000" lower="-0.785398163397" upper="0.785398163397" velocity="6.5"/>
    <dynamics damping="0.1" friction="0.0"/>
  </joint>
  <transmission name="l_leg_an_r_tran">
    <type>transmission_interface/SimpleTransmission</type>
    <joint name="l_leg_an_r">
      <hardwareInterface>hardware_interface/EffortJointInterface</hardwareInterface>
    </joint>
    <actuator name="l_leg_an_r_motor">
      <hardwareInterface>hardware_interface/EffortJointInterface</hardwareInterface>
      <mechanicalReduction>1</mechanicalReduction>
    </actuator>
  </transmission>
  <!-- ankle roll link -->
  <link name="l_leg_an_r_link">
    <collision>
      <origin rpy="0 0 0" xyz="-0.067 0 -0.02"/>
      <geometry>
        <box size="0.17 0.06 0.12"/>
      </geometry>
    </collision>
    <visual>
      <origin rpy="0 0 0" xyz="0 0 0"/>
      <geometry>
        <mesh filename="package://thormang3_description/meshes/robotis_l_leg_an_r_link.stl" scale="0.001 0.001 0.001"/>
      </geometry>
      <material name="grey"/>
    </visual>
    <inertial>
      <origin rpy="0 0 0" xyz="-0.070 0.0 -0.048"/>
      <mass value="0.223"/>
      <inertia ixx="1.0" ixy="0.0" ixz="0.0" iyy="1.0" iyz="0.0" izz="1.0"/>
      <!-- <inertia ixx="0.00022" ixy="0.0" ixz="-0.00001" iyy="0.00099" iyz="0.0" izz="0.00091" /> -->
    </inertial>
  </link>
  <!-- ft joint -->
  <!--use "fixed" revolute joint for FT sensor simulation-->
  <joint name="l_leg_ft" type="revolute">
    <origin rpy="3.14159265359 0 3.14159265359" xyz="-0.057 0.0 -0.087"/>
    <parent link="l_leg_an_r_link"/>
    <child link="l_foot_ft_link"/>
    <limit effort="1000" lower="0" upper="0" velocity="6.5"/>
  </joint>
  <!-- foot ft link -->
  <link name="l_foot_ft_link">
        </link>
  <!-- ft fixed joint -->
  <joint name="l_leg_ft_fixed" type="fixed">
    <origin rpy="3.14159265359 0 3.14159265359" xyz="0 0.0 0.0275"/>
    <parent link="l_foot_ft_link"/>
    <child link="l_leg_foot_link"/>
  </joint>
  <!-- foot link -->
  <link name="l_leg_foot_link">
    <collision>
      <origin rpy="0 0 0" xyz="0.0 0.014 0.0075"/>
      <geometry>
        <box size="0.22 0.15 0.015"/>
      </geometry>
    </collision>
    <visual>
      <origin rpy="0 0 0" xyz="0 0.0 0.0275"/>
      <geometry>
        <mesh filename="package://thormang3_description/meshes/robotis_l_leg_foot.stl" scale="0.001 0.001 0.001"/>
      </geometry>
      <material name="grey"/>
    </visual>
    <inertial>
      <origin rpy="0 0 0" xyz="0.000 0.009 -0.013"/>
      <mass value="1.689"/>
      <inertia ixx="1.0" ixy="0.0" ixz="0.0" iyy="1.0" iyz="0.0" izz="1.0"/>
      <!-- <inertia ixx="0.00219" ixy="0.0" ixz="0.0" iyy="0.00433" iyz="0.00011" izz="0.00609" /> -->
    </inertial>
  </link>
  <!-- hip yaw joint -->
  <joint name="r_leg_hip_y" type="revolute">
    <axis xyz="0 0 -1"/>
    <origin rpy="0 0 0" xyz="0.0 -0.093 -0.018"/>
    <parent link="pelvis_link"/>
    <child link="r_leg_hip_y_link"/>
    <limit effort="1000" lower="-1.41371669412" upper="1.41371669412" velocity="6.5"/>
    <dynamics damping="0.1" friction="0.0"/>
  </joint>
  <transmission name="r_leg_hip_y_tran">
    <type>transmission_interface/SimpleTransmission</type>
    <joint name="r_leg_hip_y">
      <hardwareInterface>hardware_interface/EffortJointInterface</hardwareInterface>
    </joint>
    <actuator name="r_leg_hip_y_motor">
      <hardwareInterface>hardware_interface/EffortJointInterface</hardwareInterface>
      <mechanicalReduction>1</mechanicalReduction>
    </actuator>
  </transmission>
  <!-- hip yaw link -->
  <link name="r_leg_hip_y_link">
    <collision>
      <origin rpy="0 0 0" xyz="-0.01 0 -0.05"/>
      <geometry>
        <box size="0.17 0.07 0.1"/>
      </geometry>
    </collision>
    <visual>
      <origin rpy="0 0 0" xyz="0 0 0"/>
      <geometry>
        <mesh filename="package://thormang3_description/meshes/robotis_r_leg_hip_y_link.stl" scale="0.001 0.001 0.001"/>
      </geometry>
      <material name="grey"/>
    </visual>
    <inertial>
      <origin rpy="0 0 0" xyz="0.012 -0.0 -0.025"/>
      <mass value="0.243"/>
      <inertia ixx="1.0" ixy="0.0" ixz="0.0" iyy="1.0" iyz="0.0" izz="1.0"/>
      <!-- <inertia ixx="0.00024" ixy="0.0" ixz="0.0" iyy="0.00101" iyz="0.0" izz="0.00092" /> -->
    </inertial>
  </link>
  <!-- hip roll joint -->
  <joint name="r_leg_hip_r" type="revolute">
    <axis xyz="-1 0 0"/>
    <origin rpy="0 0 0" xyz="0.057 0.0 -0.075"/>
    <parent link="r_leg_hip_y_link"/>
    <child link="r_leg_hip_r_link"/>
    <limit effort="1000" lower="-0.628318530718" upper="0.628318530718" velocity="6.5"/>
    <dynamics damping="0.1" friction="0.0"/>
  </joint>
  <transmission name="r_leg_hip_r_tran">
    <type>transmission_interface/SimpleTransmission</type>
    <joint name="r_leg_hip_r">
      <hardwareInterface>hardware_interface/EffortJointInterface</hardwareInterface>
    </joint>
    <actuator name="r_leg_hip_r_motor">
      <hardwareInterface>hardware_interface/EffortJointInterface</hardwareInterface>
      <mechanicalReduction>1</mechanicalReduction>
    </actuator>
  </transmission>
  <!-- hip roll link -->
  <link name="r_leg_hip_r_link">
    <!--
          <collision>
              <origin xyz="-0.057 0 0" rpy="0 0 0"/>
              <geometry>
                <box size="0.01 0.01 0.01" />
              </geometry>
          </collision>
  -->
    <visual>
      <origin rpy="0 0 0" xyz="0 0 0"/>
      <geometry>
        <mesh filename="package://thormang3_description/meshes/robotis_r_leg_hip_r_link.stl" scale="0.001 0.001 0.001"/>
      </geometry>
      <material name="grey"/>
    </visual>
    <inertial>
      <origin rpy="0 0 0" xyz="-0.068 -0.0 0.000"/>
      <mass value="1.045"/>
      <inertia ixx="1.0" ixy="0.0" ixz="0.0" iyy="1.0" iyz="0.0" izz="1.0"/>
      <!-- <inertia ixx="0.00056" ixy="0.0" ixz="0.0" iyy="0.00168" iyz="0.0" izz="0.00171" /> -->
    </inertial>
  </link>
  <!-- hip pitch joint -->
  <joint name="r_leg_hip_p" type="revolute">
    <axis xyz="0 -1 0"/>
    <origin rpy="0 0 0" xyz="-0.057 -0.033 0.0"/>
    <parent link="r_leg_hip_r_link"/>
    <child link="r_leg_hip_p_link"/>
    <limit effort="1000" lower="-0.785398163397" upper="1.25663706144" velocity="6.5"/>
    <dynamics damping="0.1" friction="0.0"/>
  </joint>
  <transmission name="r_leg_hip_p_tran">
    <type>transmission_interface/SimpleTransmission</type>
    <joint name="r_leg_hip_p">
      <hardwareInterface>hardware_interface/EffortJointInterface</hardwareInterface>
    </joint>
    <actuator name="r_leg_hip_p_motor">
      <hardwareInterface>hardware_interface/EffortJointInterface</hardwareInterface>
      <mechanicalReduction>1</mechanicalReduction>
    </actuator>
  </transmission>
  <!-- hip pitch link -->
  <link name="r_leg_hip_p_link">
    <collision>
      <origin rpy="0 0 0" xyz="0 0.005 -0.135"/>
      <geometry>
        <box size="0.11 0.16 0.34"/>
      </geometry>
    </collision>
    <visual>
      <origin rpy="0 0 0" xyz="0 0 0"/>
      <geometry>
        <mesh filename="package://thormang3_description/meshes/robotis_r_leg_hip_p_link.stl" scale="0.001 0.001 0.001"/>
      </geometry>
      <material name="grey"/>
    </visual>
    <inertial>
      <origin rpy="0 0 0" xyz="0.022 0.007 -0.168"/>
      <mass value="3.095"/>
      <inertia ixx="1.0" ixy="0.0" ixz="0.0" iyy="1.0" iyz="0.0" izz="1.0"/>
      <!-- <inertia ixx="0.04328" ixy="0.00028" ixz="0.00288" iyy="0.04042" iyz="-0.00202" izz="0.00560" /> -->
    </inertial>
  </link>
  <!-- knee pitch joint -->
  <joint name="r_leg_kn_p" type="revolute">
    <axis xyz="0 -1 0"/>
    <origin rpy="0 0 0" xyz="0.0 -0.06 -0.3"/>
    <parent link="r_leg_hip_p_link"/>
    <child link="r_leg_kn_p_link"/>
    <limit effort="1000" lower="-1.88495559215" upper="1.41371669412" velocity="6.5"/>
    <dynamics damping="0.1" friction="0.0"/>
  </joint>
  <transmission name="r_leg_kn_p_tran">
    <type>transmission_interface/SimpleTransmission</type>
    <joint name="r_leg_kn_p">
      <hardwareInterface>hardware_interface/EffortJointInterface</hardwareInterface>
    </joint>
    <actuator name="r_leg_kn_p_motor">
      <hardwareInterface>hardware_interface/EffortJointInterface</hardwareInterface>
      <mechanicalReduction>1</mechanicalReduction>
    </actuator>
  </transmission>
  <!-- knee pitch link -->
  <link name="r_leg_kn_p_link">
    <collision>
      <origin rpy="0 0 0" xyz="0.01 0.065 -0.145"/>
      <geometry>
        <box size="0.11 0.16 0.33"/>
      </geometry>
    </collision>
    <visual>
      <origin rpy="0 0 0" xyz="0 0 0"/>
      <geometry>
        <mesh filename="package://thormang3_description/meshes/robotis_r_leg_kn_p_link.stl" scale="0.001 0.001 0.001"/>
      </geometry>
      <material name="grey"/>
    </visual>
    <inertial>
      <origin rpy="0 0 0" xyz="-0.002 0.066 -0.183"/>
      <mass value="2.401"/>
      <inertia ixx="1.0" ixy="0.0" ixz="0.0" iyy="1.0" iyz="0.0" izz="1.0"/>
      <!-- <inertia ixx="0.01971" ixy="0.00031" ixz="-0.00294" iyy="0.01687" iyz="0.00140" izz="0.00574" /> -->
    </inertial>
  </link>
  <!-- ankle pitch joint -->
  <joint name="r_leg_an_p" type="revolute">
    <axis xyz="0 1 0"/>
    <origin rpy="0 0 0" xyz="0.0 0.06 -0.3"/>
    <parent link="r_leg_kn_p_link"/>
    <child link="r_leg_an_p_link"/>
    <limit effort="1000" lower="-1.41371669412" upper="1.41371669412" velocity="6.5"/>
    <dynamics damping="0.1" friction="0.0"/>
  </joint>
  <transmission name="r_leg_an_p_tran">
    <type>transmission_interface/SimpleTransmission</type>
    <joint name="r_leg_an_p">
      <hardwareInterface>hardware_interface/EffortJointInterface</hardwareInterface>
    </joint>
    <actuator name="r_leg_an_p_motor">
      <hardwareInterface>hardware_interface/EffortJointInterface</hardwareInterface>
      <mechanicalReduction>1</mechanicalReduction>
    </actuator>
  </transmission>
  <!-- ankle pitch link -->
  <link name="r_leg_an_p_link">
    <!--
        <collision>
            <origin xyz="0 0 0" rpy="0 0 0"/>
            <geometry>
              <box size="0.01 0.01 0.01" />
            </geometry>
        </collision>
-->
    <visual>
      <origin rpy="0 0 0" xyz="0 0 0"/>
      <geometry>
        <mesh filename="package://thormang3_description/meshes/robotis_r_leg_an_p_link.stl" scale="0.001 0.001 0.001"/>
      </geometry>
      <material name="grey"/>
    </visual>
    <inertial>
      <origin rpy="0 0 0" xyz="-0.011 0.033 0.000"/>
      <mass value="1.045"/>
      <inertia ixx="1.0" ixy="0.0" ixz="0.0" iyy="1.0" iyz="0.0" izz="1.0"/>
      <!-- <inertia ixx="0.00056" ixy="0.0" ixz="0.0" iyy="0.00168" iyz="0.0" izz="0.00171" /> -->
    </inertial>
  </link>
  <!-- ankle roll joint -->
  <joint name="r_leg_an_r" type="revolute">
    <axis xyz="1 0 0"/>
    <origin rpy="0 0 0" xyz="0.057 0.033 0.0"/>
    <parent link="r_leg_an_p_link"/>
    <child link="r_leg_an_r_link"/>
    <limit effort="1000" lower="-0.785398163397" upper="0.785398163397" velocity="6.5"/>
    <dynamics damping="0.1" friction="0.0"/>
  </joint>
  <transmission name="r_leg_an_r_tran">
    <type>transmission_interface/SimpleTransmission</type>
    <joint name="r_leg_an_r">
      <hardwareInterface>hardware_interface/EffortJointInterface</hardwareInterface>
    </joint>
    <actuator name="r_leg_an_r_motor">
      <hardwareInterface>hardware_interface/EffortJointInterface</hardwareInterface>
      <mechanicalReduction>1</mechanicalReduction>
    </actuator>
  </transmission>
  <!-- ankle roll link -->
  <link name="r_leg_an_r_link">
    <collision>
      <origin rpy="0 0 0" xyz="-0.067 0 -0.02"/>
      <geometry>
        <box size="0.17 0.06 0.12"/>
      </geometry>
    </collision>
    <visual>
      <origin rpy="0 0 0" xyz="0 0 0"/>
      <geometry>
        <mesh filename="package://thormang3_description/meshes/robotis_r_leg_an_r_link.stl" scale="0.001 0.001 0.001"/>
      </geometry>
      <material name="grey"/>
    </visual>
    <inertial>
      <origin rpy="0 0 0" xyz="-0.070 -0.0 -0.048"/>
      <mass value="0.223"/>
      <inertia ixx="1.0" ixy="0.0" ixz="0.0" iyy="1.0" iyz="0.0" izz="1.0"/>
      <!-- <inertia ixx="0.00022" ixy="0.0" ixz="-0.00001" iyy="0.00099" iyz="0.0" izz="0.00091" /> -->
    </inertial>
  </link>
  <!-- ft joint -->
  <!--use "fixed" revolute joint for FT sensor simulation-->
  <joint name="r_leg_ft" type="revolute">
    <origin rpy="3.14159265359 0 3.14159265359" xyz="-0.057 0.0 -0.087"/>
    <parent link="r_leg_an_r_link"/>
    <child link="r_foot_ft_link"/>
    <limit effort="1000" lower="0" upper="0" velocity="6.5"/>
  </joint>
  <!-- foot ft link -->
  <link name="r_foot_ft_link">
        </link>
  <!-- ft fixed joint -->
  <joint name="r_leg_ft_fixed" type="fixed">
    <origin rpy="3.14159265359 0 3.14159265359" xyz="0 0.0 0.0275"/>
    <parent link="r_foot_ft_link"/>
    <child link="r_leg_foot_link"/>
  </joint>
  <!-- foot link -->
  <link name="r_leg_foot_link">
    <collision>
      <origin rpy="0 0 0" xyz="0.0 -0.014 0.0075"/>
      <geometry>
        <box size="0.22 0.15 0.015"/>
      </geometry>
    </collision>
    <visual>
      <origin rpy="0 0 0" xyz="0 0.0 0.0275"/>
      <geometry>
        <mesh filename="package://thormang3_description/meshes/robotis_r_leg_foot.stl" scale="0.001 0.001 0.001"/>
      </geometry>
      <material name="grey"/>
    </visual>
    <inertial>
      <origin rpy="0 0 0" xyz="0.000 -0.009 -0.013"/>
      <mass value="1.689"/>
      <inertia ixx="1.0" ixy="0.0" ixz="0.0" iyy="1.0" iyz="0.0" izz="1.0"/>
      <!-- <inertia ixx="0.00219" ixy="0.0" ixz="0.0" iyy="0.00433" iyz="0.00011" izz="0.00609" /> -->
    </inertial>
  </link>
  <!-- head yaw joint -->
  <joint name="head_y" type="revolute">
    <axis xyz="0 0 1"/>
    <origin rpy="0 0 0" xyz="0.0 0.0 0.229"/>
    <parent link="chest_link"/>
    <child link="head_y_link"/>
    <limit effort="1000" lower="-1.57079632679" upper="1.57079632679" velocity="6.5"/>
    <dynamics damping="0.1" friction="0.0"/>
  </joint>
  <transmission name="head_y_tran">
    <type>transmission_interface/SimpleTransmission</type>
    <joint name="head_y">
      <hardwareInterface>hardware_interface/EffortJointInterface</hardwareInterface>
    </joint>
    <actuator name="head_y_motor">
      <hardwareInterface>hardware_interface/EffortJointInterface</hardwareInterface>
      <mechanicalReduction>1</mechanicalReduction>
    </actuator>
  </transmission>
  <!-- head yaw link -->
  <link name="head_y_link">
    <collision>
      <origin rpy="0 0 0" xyz="0 0 0.005"/>
      <geometry>
        <box size="0.05 0.1 0.01"/>
      </geometry>
    </collision>
    <visual>
      <origin rpy="0 0 0" xyz="0 0 0"/>
      <geometry>
        <mesh filename="package://thormang3_description/meshes/robotis_head_y_link.stl" scale="0.001 0.001 0.001"/>
      </geometry>
      <material name="grey"/>
    </visual>
    <inertial>
      <origin rpy="0 0 0" xyz="0.0 -0.002 0.010"/>
      <mass value="0.087"/>
      <inertia ixx="1.0" ixy="0.0" ixz="0.0" iyy="1.0" iyz="0.0" izz="1.0"/>
    </inertial>
  </link>
  <!-- head pitch joint -->
  <joint name="head_p" type="revolute">
    <axis xyz="0 1 0"/>
    <origin rpy="0 0 0" xyz="0.0 -0.045 0.039"/>
    <parent link="head_y_link"/>
    <child link="head_p_link"/>
    <limit effort="1000" lower="-0.745" upper="1.301" velocity="6.5"/>
    <dynamics damping="0.1" friction="0.0"/>
  </joint>
  <transmission name="head_p_tran">
    <type>transmission_interface/SimpleTransmission</type>
    <joint name="head_p">
      <hardwareInterface>hardware_interface/EffortJointInterface</hardwareInterface>
    </joint>
    <actuator name="head_p_motor">
      <hardwareInterface>hardware_interface/EffortJointInterface</hardwareInterface>
      <mechanicalReduction>1</mechanicalReduction>
    </actuator>
  </transmission>
  <!-- head pitch link -->
  <link name="head_p_link">
    <collision>
      <origin rpy="0 0 0" xyz="0.0 0.045 0.0"/>
      <geometry>
        <box size="0.04 0.1 0.04"/>
      </geometry>
    </collision>
    <visual>
      <origin rpy="1.57079632679 0 0" xyz="0 0 0"/>
      <geometry>
        <mesh filename="package://thormang3_description/meshes/robotis_head_p_link.stl" scale="0.001 0.001 0.001"/>
      </geometry>
      <material name="grey"/>
    </visual>
    <inertial>
      <origin rpy="0 0 0" xyz="0.009 0.046 0.022"/>
      <mass value="0.724"/>
      <inertia ixx="1.0" ixy="0.0" ixz="0.0" iyy="1.0" iyz="0.0" izz="1.0"/>
    </inertial>
  </link>
  <!-- multisensor head joint -->
  <joint name="multisensor_head_link" type="fixed">
    <origin rpy="0 0 0" xyz="0.0 0.042 0.021"/>
    <parent link="head_p_link"/>
    <child link="head_link"/>
  </joint>
  <link name="head_link">
    <inertial>
      <mass value="0.8"/>
      <inertia ixx="0.0025" ixy="0.0" ixz="0.0001" iyy="0.0013" iyz="0.0" izz="0.0026"/>
    </inertial>
    <collision name="collision">
      <origin rpy="1.5707963268 0.0 1.5707963268" xyz="0.0 0.0 0.0"/>
      <geometry>
        <mesh filename="package://hector_components_description/meshes/hector_multisensor_head/multisensor_head_collision.stl" scale="0.001 0.001 0.001"/>
      </geometry>
    </collision>
    <visual>
      <origin rpy="1.5707963268 0.0 1.5707963268" xyz="0.0 0.0 0.0"/>
      <geometry>
        <mesh filename="package://hector_components_description/meshes/hector_multisensor_head/multisensor_head.stl" scale="0.001 0.001 0.001"/>
      </geometry>
      <material name="grey"/>
    </visual>
  </link>
  <joint name="head_lidar_spinning_joint" type="continuous">
    <!--         <origin xyz="0.061 0.0 0.134" rpy="0 0 0" />-->
    <origin rpy="0 0 0" xyz="0.061 0.0 0.083"/>
    <parent link="head_link"/>
    <child link="head_lidar_mount_link"/>
    <axis rpy="0 0 0" xyz="1 0 0"/>
    <limit effort="1000" velocity="100"/>
    <joint_properties damping="500.0" friction="200.0"/>
  </joint>
  <link name="head_lidar_mount_link">
    <inertial>
      <origin rpy="0 0 0" xyz="0.0 0.0 0.0"/>
      <mass value="0.1"/>
      <inertia ixx="9e-06" ixy="0.0" ixz="0.0" iyy="9e-06" iyz="0.0" izz="9e-06"/>
    </inertial>
  </link>
  <joint name="head_link_hokuyo_laser_joint" type="fixed">
    <origin rpy="3.14159 3.11752 3.14058" xyz="0 -0.00237062 0.0100379"/>
    <parent link="head_lidar_mount_link"/>
    <child link="head_link_hokuyo_laser_frame"/>
  </joint>
  <link name="head_link_hokuyo_laser_frame">
    <inertial>
      <mass value="0.270"/>
      <origin rpy="0 0 0" xyz="0 0 0"/>
      <inertia ixx="2.632e-4" ixy="0" ixz="0" iyy="2.632e-4" iyz="0" izz="1.62e-4"/>
    </inertial>
    <visual>
      <origin rpy="0 0 0" xyz="0 0 0"/>
      <geometry>
        <mesh filename="package://hector_sensors_description/meshes/hokuyo_utm30lx/hokuyo_utm_30lx.dae"/>
      </geometry>
    </visual>
    <collision>
      <origin rpy="0 1.5707963268 0" xyz="0.00 0 0.0"/>
      <geometry>
        <cylinder length="0.079" radius="0.0735"/>
        <!--<mesh filename="package://hector_sensors_description/meshes/hokuyo_utm30lx/hokuyo_utm_30lx.stl"/>-->
      </geometry>
    </collision>
  </link>
  <gazebo reference="head_link_hokuyo_laser_frame">
    <sensor name="head_link_hokuyo_laser" type="ray">
      <always_on>true</always_on>
      <update_rate>40</update_rate>
      <pose>0 0 0 0 0 0</pose>
      <visualize>false</visualize>
      <ray>
        <scan>
          <horizontal>
            <samples>1040</samples>
            <resolution>1</resolution>
            <min_angle>2.26892802759</min_angle>
            <max_angle>-2.26892802759</max_angle>
          </horizontal>
        </scan>
        <range>
          <min>0.08</min>
          <max>30.0</max>
          <resolution>0.01</resolution>
        </range>
        <noise>
          <type>gaussian</type>
          <mean>0.0</mean>
          <stddev>0.004</stddev>
        </noise>
      </ray>
      <plugin filename="libgazebo_ros_laser.so" name="gazebo_ros_head_link_hokuyo_laser_controller">
        <gaussianNoise>0.005</gaussianNoise>
        <hokuyoMinIntensity>2000</hokuyoMinIntensity>
        <alwaysOn>true</alwaysOn>
        <robotNamespace>johnny5/sensor/</robotNamespace>
        <updateRate>40</updateRate>
        <topicName>head_lidar/scan</topicName>
        <frameName>head_link_hokuyo_laser_frame</frameName>
      </plugin>
    </sensor>
  </gazebo>
  <transmission name="head_lidar_spinning_joint_transmission">
    <type>transmission_interface/SimpleTransmission</type>
    <joint name="head_lidar_spinning_joint">
      <hardwareInterface>hardware_interface/EffortJointInterface</hardwareInterface>
    </joint>
    <actuator name="head_lidar_spinning_joint_motor">
      <hardwareInterface>hardware_interface/EffortJointInterface</hardwareInterface>
      <mechanicalReduction>1</mechanicalReduction>
    </actuator>
  </transmission>
  <gazebo reference="head_lidar_spinning_joint">
    <implicitSpringDamper>1</implicitSpringDamper>
  </gazebo>
  <joint name="head_cam_joint" type="fixed">
    <origin rpy="0 0.261799 0" xyz="0.015 -0.05 0.181"/>
    <parent link="head_link"/>
    <child link="head_cam_link"/>
  </joint>
  <link name="head_cam_link">
    <inertial>
      <mass value="0.200"/>
      <origin rpy="0 0 0" xyz="0 0 0"/>
      <inertia ixx="5.8083e-4" ixy="0" ixz="0" iyy="3.0833e-5" iyz="0" izz="5.9083e-4"/>
    </inertial>
    <visual>
      <origin rpy="0 0 0" xyz="0 0.051 0"/>
      <geometry>
        <!--Dimensions taken from https://software.intel.com/en-us/realsense/devkit-->
        <box size="0.007 0.130 0.02"/>
      </geometry>
      <material name="DarkGrey">
        <color rgba="0.3 0.3 0.3 1"/>
      </material>
    </visual>
    <!--        
       <collision>
          <origin xyz="0 0 0" rpy="0 0 0" />
          <geometry>
            <box size="0.035 0.185 0.025"/>
          </geometry>
        </collision>
        -->
    <collision>
      <origin rpy="0 0 0" xyz="0 0.051 0"/>
      <geometry>
        <!--Dimensions taken from https://software.intel.com/en-us/realsense/devkit-->
        <box size="0.007 0.130 0.02"/>
      </geometry>
    </collision>
  </link>
  <!--      <joint name="${name}_depth_joint" type="fixed">
        <origin xyz="0 -0.051 0.004" rpy="0 0 0" />
        <parent link="${name}_link" />
        <child link="${name}_depth_frame"/>
      </joint>

      <link name="${name}_depth_frame"/>

      <joint name="${name}_depth_optical_joint" type="fixed">
        <origin xyz="0 0 0" rpy="${-pi/2} 0.0 ${-pi/2}" />
        <parent link="${name}_depth_frame" />
        <child link="${name}_depth_optical_frame"/>
      </joint>

      <link name="${name}_depth_optical_frame"/>


      <joint name="${name}_depth_joint_aux" type="fixed">
        <origin xyz="0 0.032 0.004" rpy="0 0 0" />
        <parent link="${name}_link" />
        <child link="${name}_depth_frame_aux"/>
      </joint>

      <link name="${name}_depth_frame_aux"/>

      <joint name="${name}_depth_optical_joint_aux" type="fixed">
        <origin xyz="0 0 0" rpy="${-pi/2} 0.0 ${-pi/2}" />
        <parent link="${name}_depth_frame_aux" />
        <child link="${name}_depth_optical_frame_aux"/>
      </joint>

      <link name="${name}_depth_optical_frame_aux"/>


      <joint name="${name}_rgb_joint" type="fixed">
        <origin xyz="0 -0.045 0.004" rpy="0 0 0" />
        <parent link="${name}_link" />
        <child link="${name}_rgb_frame"/>
      </joint>

      <link name="${name}_rgbd_cam_link"/>

      <joint name="${name}_rgb_optical_joint" type="fixed">
        <origin xyz="0 0 0" rpy="${-pi/2} 0.0 ${-pi/2}" />
        <parent link="${name}_rgb_frame" />
        <child link="${name}_rgb_optical_frame"/>
      </joint>

      <link name="${name}_rgb_optical_frame"/>-->
  <gazebo reference="head_cam_link">
    <material>Gazebo/Blue</material>
  </gazebo>
  <gazebo reference="head_cam_link">
    <sensor name="head_cam_rgb" type="camera">
      <always_on>1</always_on>
      <update_rate>30</update_rate>
      <camera>
        <horizontal_fov>1.2217304764</horizontal_fov>
        <image>
          <format>B8G8R8</format>
          <width>1920</width>
          <height>1080</height>
        </image>
        <clip>
          <near>0.001</near>
          <far>100</far>
        </clip>
        <distortion>
          <k1>0.0</k1>
          <k2>0.0</k2>
          <k3>0.0</k3>
          <p1>-0.0</p1>
          <p2>-0.00</p2>
          <center>0.5 0.5</center>
        </distortion>
      </camera>
      <plugin filename="libgazebo_ros_camera.so" name="head_cam_camera_depth_controller">
        <robotNamespace>johnny5/sensor/head_cam/rgb</robotNamespace>
        <imageTopicName>image_raw</imageTopicName>
        <cameraInfoTopicName>camera_info</cameraInfoTopicName>
        <frameName>head_cam_rgb_optical_frame</frameName>
      </plugin>
    </sensor>
    <sensor name="head_cam_depth" type="depth">
      <update_rate>20</update_rate>
      <camera>
        <horizontal_fov>1.02974425868</horizontal_fov>
        <image>
          <format>B8G8R8</format>
          <width>640</width>
          <height>480</height>
        </image>
        <clip>
          <near>0.5</near>
          <far>10.0</far>
        </clip>
      </camera>
      <plugin filename="libgazebo_ros_openni_kinect.so" name="head_cam_camera_rgb_controller">
        <robotNamespace>johnny5/sensor/head_cam</robotNamespace>
        <imageTopicName>ir/image_raw</imageTopicName>
        <cameraInfoTopicName>ir/camera_info</cameraInfoTopicName>
        <depthImageTopicName>depth/image_raw</depthImageTopicName>
        <depthImageCameraInfoTopicName>depth/camera_info</depthImageCameraInfoTopicName>
        <pointCloudTopicName>depth/points</pointCloudTopicName>
        <frameName>head_cam_depth_optical_frame</frameName>
      </plugin>
    </sensor>
  </gazebo>
  <!-- <gazebo reference="${name}_spinning_lidar_root_link"><material>Gazebo/Grey</material></gazebo><gazebo reference="${name}_spinning_lidar_spin_link"><material>Gazebo/Grey</material></gazebo> -->
</robot>
