<?xml version="1.0"?>
<robot xmlns:xacro="http://ros.org/wiki/xacro">	

    <xacro:property name="pi" value="3.141592654" />
    <xacro:include filename="$(find hector_components_description)/urdf/hector_multisensor_head.urdf.xacro" /> 

    <xacro:macro name="thormang3_head" params="parent">

	<!-- head yaw joint -->
        <joint name="head_y" type="revolute">
          <axis xyz="0 0 1" />		
          <origin xyz="0.0 0.0 0.229" rpy="0 0 0"/>
          <parent link="${parent}"/>
          <child link="head_y_link"/>
          <limit velocity="6.5" effort="1000" lower="${-pi*0.5}" upper="${pi*0.5}" />
          <dynamics damping="0.1" friction="0.0" />
        </joint> 
        <xacro:insert_transmission name="head_y" />

	<!-- head yaw link -->
        <link name="head_y_link">
    	  <collision>
      	    <origin xyz="0 0 0.005" rpy="0 0 0"/>
      	    <geometry>
              <box size="0.05 0.1 0.01" />
      	    </geometry>
    	  </collision>

   	  <visual>
      	    <origin xyz="0 0 0" rpy="0 0 0"/>
      	    <geometry>
              <mesh filename="package://thormang3_description/meshes/robotis_head_y_link.stl" scale="0.001 0.001 0.001"/>
      	    </geometry>
      	    <material name="grey"/>
    	  </visual>

          <inertial>
      	    <origin xyz="0.0 0.0 0.0" rpy="0 0 0"/>
      	    <mass value="1.0"/>
      	    <inertia ixx="1.0" ixy="0.0" ixz="0.0" iyy="1.0" iyz="0.0" izz="1.0" /> 
    	  </inertial>
        </link>

	<!-- head pitch joint -->
        <joint name="head_p" type="revolute">
          <axis xyz="0 1 0" />		
          <origin xyz="0.0 -0.045 0.039" rpy="0 0 0"/>
          <parent link="head_y_link"/>
          <child link="head_p_link"/>
          <limit velocity="6.5" effort="1000" lower="-0.745" upper="1.301" />
          <dynamics damping="0.1" friction="0.0" />
        </joint> 
        <xacro:insert_transmission name="head_p" />
	
	<!-- head pitch link -->
        <link name="head_p_link">
    	  <collision>
      	    <origin xyz="0.0 0.045 0.0" rpy="0 0 0"/>
      	    <geometry>
              <box size="0.04 0.1 0.04" />
      	    </geometry>
    	  </collision>

   	  <visual>
      	    <origin xyz="0 0 0" rpy="${pi*0.5} 0 0"/>
      	    <geometry>
              <mesh filename="package://thormang3_description/meshes/robotis_head_p_link.stl" scale="0.001 0.001 0.001"/>
      	    </geometry>
      	    <material name="grey"/>
    	  </visual>

          <inertial>
      	    <origin xyz="0.0 0.0 0.0" rpy="0 0 0"/>
      	    <mass value="1.0"/>
      	    <inertia ixx="1.0" ixy="0.0" ixz="0.0" iyy="1.0" iyz="0.0" izz="1.0" /> 
    	  </inertial>
        </link>

	<!-- multisensor head joint -->
        <joint name="multisensor_head_link" type="fixed">
          <origin xyz="0.0 0.042 0.021" rpy="0 0 0"/>
          <parent link="head_p_link"/>
          <child link="head_link"/>
        </joint> 

	
	<hector_multisensor_head_macro parent="head_y_link"  name="head" scaling="0.001">
	  <origin xyz="0.0 0.0 0.0" rpy="${M_PI*0.5} 0.0 ${M_PI*0.5}"/>
	  <!-- Calibrated origin of the laser scanner-->
	  <origin xyz="0.0 0.000323461 0.0127965" rpy="0.0 0.021197 -0.00357142"/> 
	</hector_multisensor_head_macro>

    </xacro:macro>


</robot>
